Workbook
Name BizName: Settings!$B$5
Name BSAD: BS_AD_Lookup!$A$2:$B$6940
Name FAT_MULT: Settings!$B$58
Name PartyTypes: Settings!$J$16:$J$55
Name PayModes: Settings!$F$16:$F$55
Name Products: Settings!$H$16:$H$55
Name RateTypes: Settings!$K$16:$K$55
Name SNF_MULT: Settings!$B$59
Name Statuses: Settings!$I$16:$I$55
Name TxnTypes: Settings!$G$16:$G$55
Name Units: Settings!$E$16:$E$55

Sheet Dashboard
A1: 🐄 [Your Dairy Plant Name] — 📊 Accounts Dashboard — all figures auto-calculate from your entries
A2: 💰 TOTAL SALES | C2: 📦 TOTAL PURCHASES | E2: 📋 STOCK VALUE | G2: ⚠️ LOW STOCK ITEMS
A3: =SUM(Sales_Entry!J3:J1859) -> 3734275.3 | C3: =SUM(Purchase_Entry!P3:P1326) -> 3264264.2 | E3: =SUM(Stock_Master!I:I) | G3: =COUNTIF(Stock_Master!J:J,"⚠ Reorder") -> 5
A4: \
A5: 📤 RECEIVABLES | C5: 📥 PAYABLES | E5: 👥 TOTAL PARTIES | G5: 💰 DAYBOOK BALANCE
A6: =SUMIF(Party_Master!H:H,">0",Party_Master!H:H) -> 1773410.2 | C6: =-SUMIF(Party_Master!H:H,"<0",Party_Master!H:H) -> 1165789.6 | E6: =COUNTA(Party_Master!A3:A498) -> 66 | G6: =IFERROR(LOOKUP(2,1/(Daybook!H3:H502<>""),Daybook!H3:H502),0) -> 70776.15
A7: 📈 NET PROFIT / LOSS (Sales − Purchases): | D7: =SUM(Sales_Entry!J22:J1859)-SUM(Purchase_Entry!P9:P1326) -> 544021.07
A10: Metric | B10: Amount
A11: Total Sales | B11: =SUM(Sales_Entry!J22:J1859) -> 3202290.3
A12: Total Purchases | B12: =SUM(Purchase_Entry!P9:P1326) -> 2658269.2
A13: Stock Value | B13: =SUM(Stock_Master!I3:I41) -> -215069
A104: BS date filter works on TEXT. Type e.g. 2083/03/32 in BS format; day-32 is auto-capped to 31 in calculations.

Sheet Profit_Loss
A1: 🐄 [Your Dairy Plant Name] — 📈 Profit & Loss Account — company financial status
A3: From Date ► | B3: =IFERROR(VLOOKUP(TEXT($B$4,"yyyy/mm/dd"),BSAD,2,FALSE),IFERROR(VLOOKUP($B$4,BSAD,2,FALSE),"")) -> 46202 | C3: To Date ► | D3: =IFERROR(VLOOKUP(TEXT($D$4,"yyyy/mm/dd"),BSAD,2,FALSE),IFERROR(VLOOKUP($D$4,BSAD,2,FALSE),"")) -> 46281
A4: ="For period: "&TEXT($B$3,"dd-mmm-yyyy")&" to "&TEXT($D$3,"dd-mmm-yyyy") -> For period: 29-Jun-2026 to 16-Sep-2026 | B4: 66915 | D4: 66992
A6: 💰 INCOME
A7: Total Sales Revenue | C7: =SUMIFS(Sales_Entry!$J:$J,Sales_Entry!$B:$B,">="&$B$3,Sales_Entry!$B:$B,"<="&$D$3) -> 3734275.3
A8: Other Income (from Daybook receipts) | C8: =SUMIFS(Daybook!$G:$G,Daybook!$D:$D,"Receipt",Daybook!$B:$B,">="&$B$3,Daybook!$B:$B,"<="&$D$3) -> 0
A9: GROSS INCOME (A) | C9: =C7 -> 3734275.3
A11: 📦 COST OF GOODS / PURCHASES
A12: CASH INVESTMENT | C12: =SUMIFS(Party_Ledger!H:H,Party_Ledger!D:D,"KESHAB GAUTAM",Party_Ledger!$B:$B,">="&$B$3,Party_Ledger!$B:$B,"<="&$D$3) -> 400000
A13: Total Purchases (milk & materials) | C13: =SUMIFS(Purchase_Entry!$P:$P,Purchase_Entry!$B:$B,">="&$B$3,Purchase_Entry!$B:$B,"<="&$D$3) -> 3264264.2
A14: TOTAL COST (B) | C14: =C13+C12 -> 3664264.2
A16: GROSS PROFIT (A − B) | C16: =C9-C14 -> 70011.071
A18: 💸 OPERATING EXPENSES (FROM PETTY CASH)
A19: Total Payments/EXPENSES | C19: =SUMIFS(Party_Ledger!G:G,Party_Ledger!D:D,"Payment",Party_Ledger!$B:$B,">="&$B$3,Party_Ledger!$B:$B,"<="&$D$3) -> 179955
A20: Total Office Expenses | C20: =SUMIFS(Party_Ledger!G:G,Party_Ledger!D:D,"OFFICE EXPENSES",Party_Ledger!$B:$B,">="&$B$3,Party_Ledger!$B:$B,"<="&$D$3) -> 33513
A21: Total Advance | C21: =(SUMIFS(Party_Ledger!G:G,Party_Ledger!D:D,"Advance",Party_Ledger!$B:$B,">="&$B$3,Party_Ledger!$B:$B,"<="&$D$3))-(SUMIFS(Party_Ledger!H:H,Party_Ledger!D:D,"Advance Returned",Party_Ledger!$B:$B,">="&$B$3,Party_Ledger!$B:$B,"<="&$D$3)) -> 284940
A22: TOTAL EXPENSES (C) | C22: =C20+C19 -> 213468
A24: 🏆 NET PROFIT / (LOSS) = Gross Profit − Expenses | C24: =C16-C22 -> -143456.93
A26: Company Status: | C26: =IF(C24>0,"✅ PROFIT — Healthy",IF(C24=0,"➖ Break-even","🔴 LOSS — Review costs")) -> 🔴 LOSS — Review costs
A27: Net Profit Margin %: | C27: =IF(C9=0,0,C24/C9) -> -0.038416271

Sheet Receivable_Payable
A1: =BizName -> PRARAMBHA DAIRY SUPPLIERS
A2: RECEIVABLES & PAYABLES — party balances for selected period
A4: From Date ► | B4: =IFERROR(VLOOKUP(TEXT($B$5,"yyyy/mm/dd"),BSAD,2,FALSE),IFERROR(VLOOKUP($B$5,BSAD,2,FALSE),"")) -> 46202 | C4: To Date ► | D4: =IFERROR(VLOOKUP(TEXT($D$5,"yyyy/mm/dd"),BSAD,2,FALSE),IFERROR(VLOOKUP($D$5,BSAD,2,FALSE),"")) -> 46280 | E4: Total Receivable: | F4: =SUMIF(E8:E76,">0") -> 1738678.2
A5: ="Period: "&TEXT($B$4,"dd-mmm-yyyy")&" to "&TEXT($D$4,"dd-mmm-yyyy") -> Period: 29-Jun-2026 to 15-Sep-2026 | B5: 2083/03/15 | D5: 2083/05/30 | E5: Total Payable: | F5: =-SUMIF(E8:E76,"<0") -> 1139309.6
A7: Party Name | B7: Type | C7: Debit (Dr) | D7: Credit (Cr) | E7: Net Balance | F7: Class
A8: =Party_Master!$A3 -> A KALIKA CANTEEN | B8: =Party_Master!$B3 -> Customer | C8: =SUMIFS(Party_Ledger!$G:$G,Party_Ledger!$C:$C,$A8,Party_Ledger!$B:$B,">="&$B$4,Party_Ledger!$B:$B,"<="&$D$4) -> 33150 | D8: =SUMIFS(Party_Ledger!$H:$H,Party_Ledger!$C:$C,$A8,Party_Ledger!$B:$B,">="&$B$4,Party_Ledger!$B:$B,"<="&$D$4) -> 5950 | E8: =C8-D8 -> 27200 | F8: =IF(ROUND(E8,0)=0,"Settled",IF(E8>0,"Receivable","Payable")) -> Receivable
A9: =Party_Master!$A4 -> A1 KALIKA CANTEEN | B9: =Party_Master!$B4 -> Customer | C9: =SUMIFS(Party_Ledger!$G:$G,Party_Ledger!$C:$C,$A9,Party_Ledger!$B:$B,">="&$B$4,Party_Ledger!$B:$B,"<="&$D$4) -> 45050 | D9: =SUMIFS(Party_Ledger!$H:$H,Party_Ledger!$C:$C,$A9,Party_Ledger!$B:$B,">="&$B$4,Party_Ledger!$B:$B,"<="&$D$4) -> 17000 | E9: =C9-D9 -> 28050 | F9: =IF(ROUND(E9,0)=0,"Settled",IF(E9>0,"Receivable","Payable")) -> Receivable
A10: =Party_Master!$A5 -> AAMOSH KIRANA | B10: =Party_Master!$B5 -> Customer | C10: =SUMIFS(Party_Ledger!$G:$G,Party_Ledger!$C:$C,$A10,Party_Ledger!$B:$B,">="&$B$4,Party_Ledger!$B:$B,"<="&$D$4) -> 825393 | D10: =SUMIFS(Party_Ledger!$H:$H,Party_Ledger!$C:$C,$A10,Party_Ledger!$B:$B,">="&$B$4,Party_Ledger!$B:$B,"<="&$D$4) -> 511950 | E10: =C10-D10 -> 313443 | F10: =IF(ROUND(E10,0)=0,"Settled",IF(E10>0,"Receivable","Payable")) -> Receivable
A11: =Party_Master!$A6 -> AAYUSH AND AAYUSHMA | B11: =Party_Master!$B6 -> Customer | C11: =SUMIFS(Party_Ledger!$G:$G,Party_Ledger!$C:$C,$A11,Party_Ledger!$B:$B,">="&$B$4,Party_Ledger!$B:$B,"<="&$D$4) -> 22185 | D11: =SUMIFS(Party_Ledger!$H:$H,Party_Ledger!$C:$C,$A11,Party_Ledger!$B:$B,">="&$B$4,Party_Ledger!$B:$B,"<="&$D$4) -> 17485 | E11: =C11-D11 -> 4700 | F11: =IF(ROUND(E11,0)=0,"Settled",IF(E11>0,"Receivable","Payable")) -> Receivable
A12: =Party_Master!$A7 -> BAGESHWARI ICE CREAM | B12: =Party_Master!$B7 -> Customer | C12: =SUMIFS(Party_Ledger!$G:$G,Party_Ledger!$C:$C,$A12,Party_Ledger!$B:$B,">="&$B$4,Party_Ledger!$B:$B,"<="&$D$4) -> 11950 | D12: =SUMIFS(Party_Ledger!$H:$H,Party_Ledger!$C:$C,$A12,Party_Ledger!$B:$B,">="&$B$4,Party_Ledger!$B:$B,"<="&$D$4) -> 0 | E12: =C12-D12 -> 11950 | F12: =IF(ROUND(E12,0)=0,"Settled",IF(E12>0,"Receivable","Payable")) -> Receivable
A13: =Party_Master!$A8 -> BALKRISHNA GYAWALI | B13: =Party_Master!$B8 -> Customer | C13: =SUMIFS(Party_Ledger!$G:$G,Party_Ledger!$C:$C,$A13,Party_Ledger!$B:$B,">="&$B$4,Party_Ledger!$B:$B,"<="&$D$4) -> 4510 | D13: =SUMIFS(Party_Ledger!$H:$H,Party_Ledger!$C:$C,$A13,Party_Ledger!$B:$B,">="&$B$4,Party_Ledger!$B:$B,"<="&$D$4) -> 0 | E13: =C13-D13 -> 4510 | F13: =IF(ROUND(E13,0)=0,"Settled",IF(E13>0,"Receivable","Payable")) -> Receivable
A14: =Party_Master!$A9 -> BASUDEV DAIRY 316 | B14: =Party_Master!$B9 -> Supplier | C14: =SUMIFS(Party_Ledger!$G:$G,Party_Ledger!$C:$C,$A14,Party_Ledger!$B:$B,">="&$B$4,Party_Ledger!$B:$B,"<="&$D$4) -> 474131.13 | D14: =SUMIFS(Party_Ledger!$H:$H,Party_Ledger!$C:$C,$A14,Party_Ledger!$B:$B,">="&$B$4,Party_Ledger!$B:$B,"<="&$D$4) -> 693965.22 | E14: =C14-D14 -> -219834.09 | F14: =IF(ROUND(E14,0)=0,"Settled",IF(E14>0,"Receivable","Payable")) -> Payable
A15: =Party_Master!$A10 -> BHUSAL JANARAL STORE | B15: =Party_Master!$B10 -> Customer | C15: =SUMIFS(Party_Ledger!$G:$G,Party_Ledger!$C:$C,$A15,Party_Ledger!$B:$B,">="&$B$4,Party_Ledger!$B:$B,"<="&$D$4) -> 26410 | D15: =SUMIFS(Party_Ledger!$H:$H,Party_Ledger!$C:$C,$A15,Party_Ledger!$B:$B,">="&$B$4,Party_Ledger!$B:$B,"<="&$D$4) -> 16350 | E15: =C15-D15 -> 10060 | F15: =IF(ROUND(E15,0)=0,"Settled",IF(E15>0,"Receivable","Payable")) -> Receivable
A16: =Party_Master!$A11 -> BIKRAM DHUNGANA | B16: =Party_Master!$B11 -> Customer | C16: =SUMIFS(Party_Ledger!$G:$G,Party_Ledger!$C:$C,$A16,Party_Ledger!$B:$B,">="&$B$4,Party_Ledger!$B:$B,"<="&$D$4) -> 2200 | D16: =SUMIFS(Party_Ledger!$H:$H,Party_Ledger!$C:$C,$A16,Party_Ledger!$B:$B,">="&$B$4,Party_Ledger!$B:$B,"<="&$D$4) -> 2200 | E16: =C16-D16 -> 0 | F16: =IF(ROUND(E16,0)=0,"Settled",IF(E16>0,"Receivable","Payable")) -> Settled
A17: =Party_Master!$A12 -> BODESH 310 | B17: =Party_Master!$B12 -> Supplier | C17: =SUMIFS(Party_Ledger!$G:$G,Party_Ledger!$C:$C,$A17,Party_Ledger!$B:$B,">="&$B$4,Party_Ledger!$B:$B,"<="&$D$4) -> 310000 | D17: =SUMIFS(Party_Ledger!$H:$H,Party_Ledger!$C:$C,$A17,Party_Ledger!$B:$B,">="&$B$4,Party_Ledger!$B:$B,"<="&$D$4) -> 215600 | E17: =C17-D17 -> 94400 | F17: =IF(ROUND(E17,0)=0,"Settled",IF(E17>0,"Receivable","Payable")) -> Receivable
A18: =Party_Master!$A13 -> CHHATRABHUMI STORE | B18: =Party_Master!$B13 -> Customer | C18: =SUMIFS(Party_Ledger!$G:$G,Party_Ledger!$C:$C,$A18,Party_Ledger!$B:$B,">="&$B$4,Party_Ledger!$B:$B,"<="&$D$4) -> 223796 | D18: =SUMIFS(Party_Ledger!$H:$H,Party_Ledger!$C:$C,$A18,Party_Ledger!$B:$B,">="&$B$4,Party_Ledger!$B:$B,"<="&$D$4) -> 90000 | E18: =C18-D18 -> 133796 | F18: =IF(ROUND(E18,0)=0,"Settled",IF(E18>0,"Receivable","Payable")) -> Receivable
A19: =Party_Master!$A14 -> DANDA PANI ACHARYA | B19: =Party_Master!$B14 -> Customer | C19: =SUMIFS(Party_Ledger!$G:$G,Party_Ledger!$C:$C,$A19,Party_Ledger!$B:$B,">="&$B$4,Party_Ledger!$B:$B,"<="&$D$4) -> 1100 | D19: =SUMIFS(Party_Ledger!$H:$H,Party_Ledger!$C:$C,$A19,Party_Ledger!$B:$B,">="&$B$4,Party_Ledger!$B:$B,"<="&$D$4) -> 1100 | E19: =C19-D19 -> 0 | F19: =IF(ROUND(E19,0)=0,"Settled",IF(E19>0,"Receivable","Payable")) -> Settled
... A73: =Party_Master!$A68 -> YUBARAJ AND SAMRAT | B73: =Party_Master!$B68 -> Customer | C73: =SUMIFS(Party_Ledger!$G:$G,Party_Ledger!$C:$C,$A73,Party_Ledger!$B:$B,">="&$B$4,Party_Ledger!$B:$B,"<="&$D$4) -> 75650 | D73: =SUMIFS(Party_Ledger!$H:$H,Party_Ledger!$C:$C,$A73,Party_Ledger!$B:$B,">="&$B$4,Party_Ledger!$B:$B,"<="&$D$4) -> 66470 | E73: =C73-D73 -> 9180 | F73: =IF(ROUND(E73,0)=0,"Settled",IF(E73>0,"Receivable","Payable")) -> Receivable
A74: =Party_Master!$A69 -> 0
A77: TOTALS ► | C77: =SUM(C8:C76) -> 6244661.4 | D77: =SUM(D8:D76) -> 5645292.8 | E77: =SUM(E8:E76) -> 599368.62
A79: 💡 Change From/To Date — every party balance for that period recalculates. Positive = they owe you (Receivable). Negative = you owe them (Payable).
A80: 💡 Total Receivable / Total Payable shown at top-right.

Sheet Party_Statement
A1: =BizName -> PRARAMBHA DAIRY SUPPLIERS
A2: ="Phone: "&Settings!B9&" | PAN/VAT: "&Settings!B11 -> Phone: prarambhadairy@gmail.com | PAN/VAT: 152747352
A3: PARTY LEDGER STATEMENT | N3: One | O3: Twenty
N4: Two | O4: Thirty
A5: Select Party ► | C5: SAI KRIPA KSS LTD | F5: Opening (b/f): | G5: =SUMIFS(Party_Ledger!$G:$G,Party_Ledger!$C:$C,$C$5,Party_Ledger!$B:$B,"<"&$C$6)-SUMIFS(Party_Ledger!$H:$H,Party_Ledger!$C:$C,$C$5,Party_Ledger!$B:$B,"<"&$C$6) -> 0 | N5: Three | O5: Forty
A6: From Date ► | C6: =IFERROR(VLOOKUP(TEXT($C$7,"yyyy/mm/dd"),BSAD,2,FALSE),IFERROR(VLOOKUP($C$7,BSAD,2,FALSE),"")) -> 46202 | D6: To Date ► | E6: =IFERROR(VLOOKUP(TEXT($E$7,"yyyy/mm/dd"),BSAD,2,FALSE),IFERROR(VLOOKUP($E$7,BSAD,2,FALSE),"")) -> 46284 | F6: Period Debit: | G6: =SUMIFS(Party_Ledger!$G:$G,Party_Ledger!$C:$C,$C$5,Party_Ledger!$B:$B,">="&$C$6,Party_Ledger!$B:$B,"<="&$E$6) -> 370835 | N6: Four | O6: Fifty
A7: ="Period: "&TEXT($C$6,"dd-mmm-yyyy")&" to "&TEXT($E$6,"dd-mmm-yyyy") -> Period: 29-Jun-2026 to 19-Sep-2026 | C7: 66915 | E7: 66995 | F7: Period Credit: | G7: =SUMIFS(Party_Ledger!$H:$H,Party_Ledger!$C:$C,$C$5,Party_Ledger!$B:$B,">="&$C$6,Party_Ledger!$B:$B,"<="&$E$6) -> 106685 | N7: Five | O7: Sixty
F8: Closing Balance: | G8: =G5+G6-G7 -> 264150 | N8: Six | O8: Seventy
F9: Status: | G9: =IF(ROUND(G8,0)=0,"Settled",IF(G8>0,"Receivable","Payable/Advance")) -> Receivable | N9: Seven | O9: Eighty
N10: Eight | O10: Ninety
A11: Date | B11: AD Date | C11: Txn Type | D11: Reference | E11: Description | F11: Debit | G11: Credit | H11: Balance | N11: Nine
A12: =IFERROR(INDEX(Party_Ledger!$A$3:$A$100322, MATCH(ROWS($1:1), Party_Ledger!$K$3:$K$100322, 0)), "") -> 66915 | B12: =IF(A12="","",IF(ISNUMBER(A12),IFERROR(VLOOKUP(TEXT(A12,"yyyy/mm/dd"),BSAD,2,FALSE),""),IFERROR(VLOOKUP(A12,BSAD,2,FALSE),""))) -> 46202 | C12: =IFERROR(INDEX(Party_Ledger!$D$3:$D$100322,MATCH(ROWS($1:1),Party_Ledger!$K$3:$K$100322,0)),"") -> Purchase | D12: =IFERROR(INDEX(Party_Ledger!$E$3:$E$100322,MATCH(ROWS($1:1),Party_Ledger!$K$3:$K$100322,0)),"") -> S 5956 | E12: =IFERROR(INDEX(Party_Ledger!$F$3:$F$100322,MATCH(ROWS($1:1),Party_Ledger!$K$3:$K$100322,0)),"") -> Mix Milk | F12: =IFERROR(INDEX(Party_Ledger!$G$3:$G$100322,MATCH(ROWS($1:1),Party_Ledger!$K$3:$K$100322,0)),"") -> 0 | G12: =IFERROR(INDEX(Party_Ledger!$H$3:$H$100322,MATCH(ROWS($1:1),Party_Ledger!$K$3:$K$100322,0)),"") -> 16520 | H12: =IF($A12="","",N($F12)-N($G12)) -> -16520 | N12: Eleven
A13: =IFERROR(INDEX(Party_Ledger!$A$3:$A$100322, MATCH(ROWS($1:2), Party_Ledger!$K$3:$K$100322, 0)), "") -> 66915 | B13: =IF(A13="","",IF(ISNUMBER(A13),IFERROR(VLOOKUP(TEXT(A13,"yyyy/mm/dd"),BSAD,2,FALSE),""),IFERROR(VLOOKUP(A13,BSAD,2,FALSE),""))) -> 46202 | C13: =IFERROR(INDEX(Party_Ledger!$D$3:$D$100322,MATCH(ROWS($1:2),Party_Ledger!$K$3:$K$100322,0)),"") -> Purchase | D13: =IFERROR(INDEX(Party_Ledger!$E$3:$E$100322,MATCH(ROWS($1:2),Party_Ledger!$K$3:$K$100322,0)),"") -> S 5956 | E13: =IFERROR(INDEX(Party_Ledger!$F$3:$F$100322,MATCH(ROWS($1:2),Party_Ledger!$K$3:$K$100322,0)),"") -> NAUNI | F13: =IFERROR(INDEX(Party_Ledger!$G$3:$G$100322,MATCH(ROWS($1:2),Party_Ledger!$K$3:$K$100322,0)),"") -> 0 | G13: =IFERROR(INDEX(Party_Ledger!$H$3:$H$100322,MATCH(ROWS($1:2),Party_Ledger!$K$3:$K$100322,0)),"") -> 4550 | H13: =IF($A13="","",N($F13)-N($G13)) -> -4550 | N13: Thirteen
A14: =IFERROR(INDEX(Party_Ledger!$A$3:$A$100322, MATCH(ROWS($1:3), Party_Ledger!$K$3:$K$100322, 0)), "") -> 66915 | B14: =IF(A14="","",IF(ISNUMBER(A14),IFERROR(VLOOKUP(TEXT(A14,"yyyy/mm/dd"),BSAD,2,FALSE),""),IFERROR(VLOOKUP(A14,BSAD,2,FALSE),""))) -> 46202 | C14: =IFERROR(INDEX(Party_Ledger!$D$3:$D$100322,MATCH(ROWS($1:3),Party_Ledger!$K$3:$K$100322,0)),"") -> Purchase | D14: =IFERROR(INDEX(Party_Ledger!$E$3:$E$100322,MATCH(ROWS($1:3),Party_Ledger!$K$3:$K$100322,0)),"") -> S 5956 | E14: =IFERROR(INDEX(Party_Ledger!$F$3:$F$100322,MATCH(ROWS($1:3),Party_Ledger!$K$3:$K$100322,0)),"") -> Ghee | F14: =IFERROR(INDEX(Party_Ledger!$G$3:$G$100322,MATCH(ROWS($1:3),Party_Ledger!$K$3:$K$100322,0)),"") -> 0 | G14: =IFERROR(INDEX(Party_Ledger!$H$3:$H$100322,MATCH(ROWS($1:3),Party_Ledger!$K$3:$K$100322,0)),"") -> 17100 | H14: =IF($A14="","",N($F14)-N($G14)) -> -17100 | N14: Fourteen
A15: =IFERROR(INDEX(Party_Ledger!$A$3:$A$100322, MATCH(ROWS($1:4), Party_Ledger!$K$3:$K$100322, 0)), "") -> 66915 | B15: =IF(A15="","",IF(ISNUMBER(A15),IFERROR(VLOOKUP(TEXT(A15,"yyyy/mm/dd"),BSAD,2,FALSE),""),IFERROR(VLOOKUP(A15,BSAD,2,FALSE),""))) -> 46202 | C15: =IFERROR(INDEX(Party_Ledger!$D$3:$D$100322,MATCH(ROWS($1:4),Party_Ledger!$K$3:$K$100322,0)),"") -> Purchase | D15: =IFERROR(INDEX(Party_Ledger!$E$3:$E$100322,MATCH(ROWS($1:4),Party_Ledger!$K$3:$K$100322,0)),"") -> S 5956 | E15: =IFERROR(INDEX(Party_Ledger!$F$3:$F$100322,MATCH(ROWS($1:4),Party_Ledger!$K$3:$K$100322,0)),"") -> Paneer | F15: =IFERROR(INDEX(Party_Ledger!$G$3:$G$100322,MATCH(ROWS($1:4),Party_Ledger!$K$3:$K$100322,0)),"") -> 0 | G15: =IFERROR(INDEX(Party_Ledger!$H$3:$H$100322,MATCH(ROWS($1:4),Party_Ledger!$K$3:$K$100322,0)),"") -> 720 | H15: =IF($A15="","",N($F15)-N($G15)) -> -720 | N15: Fifteen
A16: =IFERROR(INDEX(Party_Ledger!$A$3:$A$100322, MATCH(ROWS($1:5), Party_Ledger!$K$3:$K$100322, 0)), "") -> 66915 | B16: =IF(A16="","",IF(ISNUMBER(A16),IFERROR(VLOOKUP(TEXT(A16,"yyyy/mm/dd"),BSAD,2,FALSE),""),IFERROR(VLOOKUP(A16,BSAD,2,FALSE),""))) -> 46202 | C16: =IFERROR(INDEX(Party_Ledger!$D$3:$D$100322,MATCH(ROWS($1:5),Party_Ledger!$K$3:$K$100322,0)),"") -> Purchase | D16: =IFERROR(INDEX(Party_Ledger!$E$3:$E$100322,MATCH(ROWS($1:5),Party_Ledger!$K$3:$K$100322,0)),"") -> S 5956 | E16: =IFERROR(INDEX(Party_Ledger!$F$3:$F$100322,MATCH(ROWS($1:5),Party_Ledger!$K$3:$K$100322,0)),"") -> Cream | F16: =IFERROR(INDEX(Party_Ledger!$G$3:$G$100322,MATCH(ROWS($1:5),Party_Ledger!$K$3:$K$100322,0)),"") -> 0 | G16: =IFERROR(INDEX(Party_Ledger!$H$3:$H$100322,MATCH(ROWS($1:5),Party_Ledger!$K$3:$K$100322,0)),"") -> 66150 | H16: =IF($A16="","",N($F16)-N($G16)) -> -66150 | N16: Sixteen
A17: =IFERROR(INDEX(Party_Ledger!$A$3:$A$100322, MATCH(ROWS($1:6), Party_Ledger!$K$3:$K$100322, 0)), "") -> 66915 | B17: =IF(A17="","",IF(ISNUMBER(A17),IFERROR(VLOOKUP(TEXT(A17,"yyyy/mm/dd"),BSAD,2,FALSE),""),IFERROR(VLOOKUP(A17,BSAD,2,FALSE),""))) -> 46202 | C17: =IFERROR(INDEX(Party_Ledger!$D$3:$D$100322,MATCH(ROWS($1:6),Party_Ledger!$K$3:$K$100322,0)),"") -> Purchase | D17: =IFERROR(INDEX(Party_Ledger!$E$3:$E$100322,MATCH(ROWS($1:6),Party_Ledger!$K$3:$K$100322,0)),"") -> S 5963 | E17: =IFERROR(INDEX(Party_Ledger!$F$3:$F$100322,MATCH(ROWS($1:6),Party_Ledger!$K$3:$K$100322,0)),"") -> Dana | F17: =IFERROR(INDEX(Party_Ledger!$G$3:$G$100322,MATCH(ROWS($1:6),Party_Ledger!$K$3:$K$100322,0)),"") -> 0 | G17: =IFERROR(INDEX(Party_Ledger!$H$3:$H$100322,MATCH(ROWS($1:6),Party_Ledger!$K$3:$K$100322,0)),"") -> 1645 | H17: =IF($A17="","",N($F17)-N($G17)) -> -1645 | N17: Seventeen
A18: =IFERROR(INDEX(Party_Ledger!$A$3:$A$100322, MATCH(ROWS($1:7), Party_Ledger!$K$3:$K$100322, 0)), "") -> 2083/03/16 | B18: =IF(A18="","",IF(ISNUMBER(A18),IFERROR(VLOOKUP(TEXT(A18,"yyyy/mm/dd"),BSAD,2,FALSE),""),IFERROR(VLOOKUP(A18,BSAD,2,FALSE),""))) -> 46203 | C18: =IFERROR(INDEX(Party_Ledger!$D$3:$D$100322,MATCH(ROWS($1:7),Party_Ledger!$K$3:$K$100322,0)),"") -> Advance | D18: =IFERROR(INDEX(Party_Ledger!$E$3:$E$100322,MATCH(ROWS($1:7),Party_Ledger!$K$3:$K$100322,0)),"") -> 0 | E18: =IFERROR(INDEX(Party_Ledger!$F$3:$F$100322,MATCH(ROWS($1:7),Party_Ledger!$K$3:$K$100322,0)),"") -> CASH | F18: =IFERROR(INDEX(Party_Ledger!$G$3:$G$100322,MATCH(ROWS($1:7),Party_Ledger!$K$3:$K$100322,0)),"") -> 190 | G18: =IFERROR(INDEX(Party_Ledger!$H$3:$H$100322,MATCH(ROWS($1:7),Party_Ledger!$K$3:$K$100322,0)),"") -> 0 | H18: =IF($A18="","",N($F18)-N($G18)) -> 190 | N18: Eighteen
A19: =IFERROR(INDEX(Party_Ledger!$A$3:$A$100322, MATCH(ROWS($1:8), Party_Ledger!$K$3:$K$100322, 0)), "") -> 66925 | B19: =IF(A19="","",IF(ISNUMBER(A19),IFERROR(VLOOKUP(TEXT(A19,"yyyy/mm/dd"),BSAD,2,FALSE),""),IFERROR(VLOOKUP(A19,BSAD,2,FALSE),""))) -> 46212 | C19: =IFERROR(INDEX(Party_Ledger!$D$3:$D$100322,MATCH(ROWS($1:8),Party_Ledger!$K$3:$K$100322,0)),"") -> Advance | D19: =IFERROR(INDEX(Party_Ledger!$E$3:$E$100322,MATCH(ROWS($1:8),Party_Ledger!$K$3:$K$100322,0)),"") -> 0 | E19: =IFERROR(INDEX(Party_Ledger!$F$3:$F$100322,MATCH(ROWS($1:8),Party_Ledger!$K$3:$K$100322,0)),"") -> SENSOE WIRE | F19: =IFERROR(INDEX(Party_Ledger!$G$3:$G$100322,MATCH(ROWS($1:8),Party_Ledger!$K$3:$K$100322,0)),"") -> 350 | G19: =IFERROR(INDEX(Party_Ledger!$H$3:$H$100322,MATCH(ROWS($1:8),Party_Ledger!$K$3:$K$100322,0)),"") -> 0 | H19: =IF($A19="","",N($F19)-N($G19)) -> 350 | N19: Nineteen
A20: =IFERROR(INDEX(Party_Ledger!$A$3:$A$100322, MATCH(ROWS($1:9), Party_Ledger!$K$3:$K$100322, 0)), "") -> 2083/04/07 | B20: =IF(A20="","",IF(ISNUMBER(A20),IFERROR(VLOOKUP(TEXT(A20,"yyyy/mm/dd"),BSAD,2,FALSE),""),IFERROR(VLOOKUP(A20,BSAD,2,FALSE),""))) -> 46226 | C20: =IFERROR(INDEX(Party_Ledger!$D$3:$D$100322,MATCH(ROWS($1:9),Party_Ledger!$K$3:$K$100322,0)),"") -> Advance | D20: =IFERROR(INDEX(Party_Ledger!$E$3:$E$100322,MATCH(ROWS($1:9),Party_Ledger!$K$3:$K$100322,0)),"") -> 0 | E20: =IFERROR(INDEX(Party_Ledger!$F$3:$F$100322,MATCH(ROWS($1:9),Party_Ledger!$K$3:$K$100322,0)),"") -> CASH | F20: =IFERROR(INDEX(Party_Ledger!$G$3:$G$100322,MATCH(ROWS($1:9),Party_Ledger!$K$3:$K$100322,0)),"") -> 3490 | G20: =IFERROR(INDEX(Party_Ledger!$H$3:$H$100322,MATCH(ROWS($1:9),Party_Ledger!$K$3:$K$100322,0)),"") -> 0 | H20: =IF($A20="","",N($F20)-N($G20)) -> 3490
A21: =IFERROR(INDEX(Party_Ledger!$A$3:$A$100322, MATCH(ROWS($1:10), Party_Ledger!$K$3:$K$100322, 0)), "") -> 2083/04/07 | B21: =IF(A21="","",IF(ISNUMBER(A21),IFERROR(VLOOKUP(TEXT(A21,"yyyy/mm/dd"),BSAD,2,FALSE),""),IFERROR(VLOOKUP(A21,BSAD,2,FALSE),""))) -> 46226 | C21: =IFERROR(INDEX(Party_Ledger!$D$3:$D$100322,MATCH(ROWS($1:10),Party_Ledger!$K$3:$K$100322,0)),"") -> Advance | D21: =IFERROR(INDEX(Party_Ledger!$E$3:$E$100322,MATCH(ROWS($1:10),Party_Ledger!$K$3:$K$100322,0)),"") -> 0 | E21: =IFERROR(INDEX(Party_Ledger!$F$3:$F$100322,MATCH(ROWS($1:10),Party_Ledger!$K$3:$K$100322,0)),"") -> CLEANING600 | F21: =IFERROR(INDEX(Party_Ledger!$G$3:$G$100322,MATCH(ROWS($1:10),Party_Ledger!$K$3:$K$100322,0)),"") -> 600 | G21: =IFERROR(INDEX(Party_Ledger!$H$3:$H$100322,MATCH(ROWS($1:10),Party_Ledger!$K$3:$K$100322,0)),"") -> 0 | H21: =IF($A21="","",N($F21)-N($G21)) -> 600
A22: =IFERROR(INDEX(Party_Ledger!$A$3:$A$100322, MATCH(ROWS($1:11), Party_Ledger!$K$3:$K$100322, 0)), "") -> 2083/04/08 | B22: =IF(A22="","",IF(ISNUMBER(A22),IFERROR(VLOOKUP(TEXT(A22,"yyyy/mm/dd"),BSAD,2,FALSE),""),IFERROR(VLOOKUP(A22,BSAD,2,FALSE),""))) -> 46227 | C22: =IFERROR(INDEX(Party_Ledger!$D$3:$D$100322,MATCH(ROWS($1:11),Party_Ledger!$K$3:$K$100322,0)),"") -> Advance | D22: =IFERROR(INDEX(Party_Ledger!$E$3:$E$100322,MATCH(ROWS($1:11),Party_Ledger!$K$3:$K$100322,0)),"") -> 0 | E22: =IFERROR(INDEX(Party_Ledger!$F$3:$F$100322,MATCH(ROWS($1:11),Party_Ledger!$K$3:$K$100322,0)),"") -> CASH | F22: =IFERROR(INDEX(Party_Ledger!$G$3:$G$100322,MATCH(ROWS($1:11),Party_Ledger!$K$3:$K$100322,0)),"") -> 3400 | G22: =IFERROR(INDEX(Party_Ledger!$H$3:$H$100322,MATCH(ROWS($1:11),Party_Ledger!$K$3:$K$100322,0)),"") -> 0 | H22: =IF($A22="","",N($F22)-N($G22)) -> 3400
A23: =IFERROR(INDEX(Party_Ledger!$A$3:$A$100322, MATCH(ROWS($1:12), Party_Ledger!$K$3:$K$100322, 0)), "") -> 2083/04/11 | B23: =IF(A23="","",IF(ISNUMBER(A23),IFERROR(VLOOKUP(TEXT(A23,"yyyy/mm/dd"),BSAD,2,FALSE),""),IFERROR(VLOOKUP(A23,BSAD,2,FALSE),""))) -> 46230 | C23: =IFERROR(INDEX(Party_Ledger!$D$3:$D$100322,MATCH(ROWS($1:12),Party_Ledger!$K$3:$K$100322,0)),"") -> Advance | D23: =IFERROR(INDEX(Party_Ledger!$E$3:$E$100322,MATCH(ROWS($1:12),Party_Ledger!$K$3:$K$100322,0)),"") -> 0 | E23: =IFERROR(INDEX(Party_Ledger!$F$3:$F$100322,MATCH(ROWS($1:12),Party_Ledger!$K$3:$K$100322,0)),"") -> SURYA KC FOR SENSOR | F23: =IFERROR(INDEX(Party_Ledger!$G$3:$G$100322,MATCH(ROWS($1:12),Party_Ledger!$K$3:$K$100322,0)),"") -> 2000 | G23: =IFERROR(INDEX(Party_Ledger!$H$3:$H$100322,MATCH(ROWS($1:12),Party_Ledger!$K$3:$K$100322,0)),"") -> 0 | H23: =IF($A23="","",N($F23)-N($G23)) -> 2000
A24: =IFERROR(INDEX(Party_Ledger!$A$3:$A$100322, MATCH(ROWS($1:13), Party_Ledger!$K$3:$K$100322, 0)), "") -> 2083/04/11 | B24: =IF(A24="","",IF(ISNUMBER(A24),IFERROR(VLOOKUP(TEXT(A24,"yyyy/mm/dd"),BSAD,2,FALSE),""),IFERROR(VLOOKUP(A24,BSAD,2,FALSE),""))) -> 46230 | C24: =IFERROR(INDEX(Party_Ledger!$D$3:$D$100322,MATCH(ROWS($1:13),Party_Ledger!$K$3:$K$100322,0)),"") -> Advance | D24: =IFERROR(INDEX(Party_Ledger!$E$3:$E$100322,MATCH(ROWS($1:13),Party_Ledger!$K$3:$K$100322,0)),"") -> 0 | E24: =IFERROR(INDEX(Party_Ledger!$F$3:$F$100322,MATCH(ROWS($1:13),Party_Ledger!$K$3:$K$100322,0)),"") -> SURYA KC FOR SENSOR | F24: =IFERROR(INDEX(Party_Ledger!$G$3:$G$100322,MATCH(ROWS($1:13),Party_Ledger!$K$3:$K$100322,0)),"") -> 5000 | G24: =IFERROR(INDEX(Party_Ledger!$H$3:$H$100322,MATCH(ROWS($1:13),Party_Ledger!$K$3:$K$100322,0)),"") -> 0 | H24: =IF($A24="","",N($F24)-N($G24)) -> 5000
A25: =IFERROR(INDEX(Party_Ledger!$A$3:$A$100322, MATCH(ROWS($1:14), Party_Ledger!$K$3:$K$100322, 0)), "") -> 2083/04/11 | B25: =IF(A25="","",IF(ISNUMBER(A25),IFERROR(VLOOKUP(TEXT(A25,"yyyy/mm/dd"),BSAD,2,FALSE),""),IFERROR(VLOOKUP(A25,BSAD,2,FALSE),""))) -> 46230 | C25: =IFERROR(INDEX(Party_Ledger!$D$3:$D$100322,MATCH(ROWS($1:14),Party_Ledger!$K$3:$K$100322,0)),"") -> Advance | D25: =IFERROR(INDEX(Party_Ledger!$E$3:$E$100322,MATCH(ROWS($1:14),Party_Ledger!$K$3:$K$100322,0)),"") -> 0 | E25: =IFERROR(INDEX(Party_Ledger!$F$3:$F$100322,MATCH(ROWS($1:14),Party_Ledger!$K$3:$K$100322,0)),"") -> WOOD | F25: =IFERROR(INDEX(Party_Ledger!$G$3:$G$100322,MATCH(ROWS($1:14),Party_Ledger!$K$3:$K$100322,0)),"") -> 900 | G25: =IFERROR(INDEX(Party_Ledger!$H$3:$H$100322,MATCH(ROWS($1:14),Party_Ledger!$K$3:$K$100322,0)),"") -> 0 | H25: =IF($A25="","",N($F25)-N($G25)) -> 900
A26: =IFERROR(INDEX(Party_Ledger!$A$3:$A$100322, MATCH(ROWS($1:15), Party_Ledger!$K$3:$K$100322, 0)), "") -> 2083/04/14 | B26: =IF(A26="","",IF(ISNUMBER(A26),IFERROR(VLOOKUP(TEXT(A26,"yyyy/mm/dd"),BSAD,2,FALSE),""),IFERROR(VLOOKUP(A26,BSAD,2,FALSE),""))) -> 46233 | C26: =IFERROR(INDEX(Party_Ledger!$D$3:$D$100322,MATCH(ROWS($1:15),Party_Ledger!$K$3:$K$100322,0)),"") -> Advance | D26: =IFERROR(INDEX(Party_Ledger!$E$3:$E$100322,MATCH(ROWS($1:15),Party_Ledger!$K$3:$K$100322,0)),"") -> 0 | E26: =IFERROR(INDEX(Party_Ledger!$F$3:$F$100322,MATCH(ROWS($1:15),Party_Ledger!$K$3:$K$100322,0)),"") -> WOOD | F26: =IFERROR(INDEX(Party_Ledger!$G$3:$G$100322,MATCH(ROWS($1:15),Party_Ledger!$K$3:$K$100322,0)),"") -> 1800 | G26: =IFERROR(INDEX(Party_Ledger!$H$3:$H$100322,MATCH(ROWS($1:15),Party_Ledger!$K$3:$K$100322,0)),"") -> 0 | H26: =IF($A26="","",N($F26)-N($G26)) -> 1800
A27: =IFERROR(INDEX(Party_Ledger!$A$3:$A$100322, MATCH(ROWS($1:16), Party_Ledger!$K$3:$K$100322, 0)), "") -> 2083/04/18 | B27: =IF(A27="","",IF(ISNUMBER(A27),IFERROR(VLOOKUP(TEXT(A27,"yyyy/mm/dd"),BSAD,2,FALSE),""),IFERROR(VLOOKUP(A27,BSAD,2,FALSE),""))) -> 46237 | C27: =IFERROR(INDEX(Party_Ledger!$D$3:$D$100322,MATCH(ROWS($1:16),Party_Ledger!$K$3:$K$100322,0)),"") -> Advance | D27: =IFERROR(INDEX(Party_Ledger!$E$3:$E$100322,MATCH(ROWS($1:16),Party_Ledger!$K$3:$K$100322,0)),"") -> 0 | E27: =IFERROR(INDEX(Party_Ledger!$F$3:$F$100322,MATCH(ROWS($1:16),Party_Ledger!$K$3:$K$100322,0)),"") -> WOOD | F27: =IFERROR(INDEX(Party_Ledger!$G$3:$G$100322,MATCH(ROWS($1:16),Party_Ledger!$K$3:$K$100322,0)),"") -> 2700 | G27: =IFERROR(INDEX(Party_Ledger!$H$3:$H$100322,MATCH(ROWS($1:16),Party_Ledger!$K$3:$K$100322,0)),"") -> 0 | H27: =IF($A27="","",N($F27)-N($G27)) -> 2700
A28: =IFERROR(INDEX(Party_Ledger!$A$3:$A$100322, MATCH(ROWS($1:17), Party_Ledger!$K$3:$K$100322, 0)), "") -> 2083/05/05 | B28: =IF(A28="","",IF(ISNUMBER(A28),IFERROR(VLOOKUP(TEXT(A28,"yyyy/mm/dd"),BSAD,2,FALSE),""),IFERROR(VLOOKUP(A28,BSAD,2,FALSE),""))) -> 46255 | C28: =IFERROR(INDEX(Party_Ledger!$D$3:$D$100322,MATCH(ROWS($1:17),Party_Ledger!$K$3:$K$100322,0)),"") -> Advance | D28: =IFERROR(INDEX(Party_Ledger!$E$3:$E$100322,MATCH(ROWS($1:17),Party_Ledger!$K$3:$K$100322,0)),"") -> 0 | E28: =IFERROR(INDEX(Party_Ledger!$F$3:$F$100322,MATCH(ROWS($1:17),Party_Ledger!$K$3:$K$100322,0)),"") -> CASH | F28: =IFERROR(INDEX(Party_Ledger!$G$3:$G$100322,MATCH(ROWS($1:17),Party_Ledger!$K$3:$K$100322,0)),"") -> 50000 | G28: =IFERROR(INDEX(Party_Ledger!$H$3:$H$100322,MATCH(ROWS($1:17),Party_Ledger!$K$3:$K$100322,0)),"") -> 0 | H28: =IF($A28="","",N($F28)-N($G28)) -> 50000
A29: =IFERROR(INDEX(Party_Ledger!$A$3:$A$100322, MATCH(ROWS($1:18), Party_Ledger!$K$3:$K$100322, 0)), "") -> 2083/05/05 | B29: =IF(A29="","",IF(ISNUMBER(A29),IFERROR(VLOOKUP(TEXT(A29,"yyyy/mm/dd"),BSAD,2,FALSE),""),IFERROR(VLOOKUP(A29,BSAD,2,FALSE),""))) -> 46255 | C29: =IFERROR(INDEX(Party_Ledger!$D$3:$D$100322,MATCH(ROWS($1:18),Party_Ledger!$K$3:$K$100322,0)),"") -> Advance | D29: =IFERROR(INDEX(Party_Ledger!$E$3:$E$100322,MATCH(ROWS($1:18),Party_Ledger!$K$3:$K$100322,0)),"") -> 0 | E29: =IFERROR(INDEX(Party_Ledger!$F$3:$F$100322,MATCH(ROWS($1:18),Party_Ledger!$K$3:$K$100322,0)),"") -> CASH | F29: =IFERROR(INDEX(Party_Ledger!$G$3:$G$100322,MATCH(ROWS($1:18),Party_Ledger!$K$3:$K$100322,0)),"") -> 139865 | G29: =IFERROR(INDEX(Party_Ledger!$H$3:$H$100322,MATCH(ROWS($1:18),Party_Ledger!$K$3:$K$100322,0)),"") -> 0 | H29: =IF($A29="","",N($F29)-N($G29)) -> 139865
A30: =IFERROR(INDEX(Party_Ledger!$A$3:$A$100322, MATCH(ROWS($1:19), Party_Ledger!$K$3:$K$100322, 0)), "") -> 2083/05/07 | B30: =IF(A30="","",IF(ISNUMBER(A30),IFERROR(VLOOKUP(TEXT(A30,"yyyy/mm/dd"),BSAD,2,FALSE),""),IFERROR(VLOOKUP(A30,BSAD,2,FALSE),""))) -> 46257 | C30: =IFERROR(INDEX(Party_Ledger!$D$3:$D$100322,MATCH(ROWS($1:19),Party_Ledger!$K$3:$K$100322,0)),"") -> Advance | D30: =IFERROR(INDEX(Party_Ledger!$E$3:$E$100322,MATCH(ROWS($1:19),Party_Ledger!$K$3:$K$100322,0)),"") -> 0 | E30: =IFERROR(INDEX(Party_Ledger!$F$3:$F$100322,MATCH(ROWS($1:19),Party_Ledger!$K$3:$K$100322,0)),"") -> FOOD FOR 4 | F30: =IFERROR(INDEX(Party_Ledger!$G$3:$G$100322,MATCH(ROWS($1:19),Party_Ledger!$K$3:$K$100322,0)),"") -> 840 | G30: =IFERROR(INDEX(Party_Ledger!$H$3:$H$100322,MATCH(ROWS($1:19),Party_Ledger!$K$3:$K$100322,0)),"") -> 0 | H30: =IF($A30="","",N($F30)-N($G30)) -> 840
A31: =IFERROR(INDEX(Party_Ledger!$A$3:$A$100322, MATCH(ROWS($1:20), Party_Ledger!$K$3:$K$100322, 0)), "") -> 2083/05/07 | B31: =IF(A31="","",IF(ISNUMBER(A31),IFERROR(VLOOKUP(TEXT(A31,"yyyy/mm/dd"),BSAD,2,FALSE),""),IFERROR(VLOOKUP(A31,BSAD,2,FALSE),""))) -> 46257 | C31: =IFERROR(INDEX(Party_Ledger!$D$3:$D$100322,MATCH(ROWS($1:20),Party_Ledger!$K$3:$K$100322,0)),"") -> Advance | D31: =IFERROR(INDEX(Party_Ledger!$E$3:$E$100322,MATCH(ROWS($1:20),Party_Ledger!$K$3:$K$100322,0)),"") -> 0 | E31: =IFERROR(INDEX(Party_Ledger!$F$3:$F$100322,MATCH(ROWS($1:20),Party_Ledger!$K$3:$K$100322,0)),"") -> ADVANCE | F31: =IFERROR(INDEX(Party_Ledger!$G$3:$G$100322,MATCH(ROWS($1:20),Party_Ledger!$K$3:$K$100322,0)),"") -> 500 | G31: =IFERROR(INDEX(Party_Ledger!$H$3:$H$100322,MATCH(ROWS($1:20),Party_Ledger!$K$3:$K$100322,0)),"") -> 0 | H31: =IF($A31="","",N($F31)-N($G31)) -> 500
A32: =IFERROR(INDEX(Party_Ledger!$A$3:$A$100322, MATCH(ROWS($1:21), Party_Ledger!$K$3:$K$100322, 0)), "") -> 2083/05/08 | B32: =IF(A32="","",IF(ISNUMBER(A32),IFERROR(VLOOKUP(TEXT(A32,"yyyy/mm/dd"),BSAD,2,FALSE),""),IFERROR(VLOOKUP(A32,BSAD,2,FALSE),""))) -> 46258 | C32: =IFERROR(INDEX(Party_Ledger!$D$3:$D$100322,MATCH(ROWS($1:21),Party_Ledger!$K$3:$K$100322,0)),"") -> Advance | D32: =IFERROR(INDEX(Party_Ledger!$E$3:$E$100322,MATCH(ROWS($1:21),Party_Ledger!$K$3:$K$100322,0)),"") -> 0 | E32: =IFERROR(INDEX(Party_Ledger!$F$3:$F$100322,MATCH(ROWS($1:21),Party_Ledger!$K$3:$K$100322,0)),"") -> CLAMP FOR VEHICLE | F32: =IFERROR(INDEX(Party_Ledger!$G$3:$G$100322,MATCH(ROWS($1:21),Party_Ledger!$K$3:$K$100322,0)),"") -> 500 | G32: =IFERROR(INDEX(Party_Ledger!$H$3:$H$100322,MATCH(ROWS($1:21),Party_Ledger!$K$3:$K$100322,0)),"") -> 0 | H32: =IF($A32="","",N($F32)-N($G32)) -> 500
A33: =IFERROR(INDEX(Party_Ledger!$A$3:$A$100322, MATCH(ROWS($1:22), Party_Ledger!$K$3:$K$100322, 0)), "") -> 2083/05/08 | B33: =IF(A33="","",IF(ISNUMBER(A33),IFERROR(VLOOKUP(TEXT(A33,"yyyy/mm/dd"),BSAD,2,FALSE),""),IFERROR(VLOOKUP(A33,BSAD,2,FALSE),""))) -> 46258 | C33: =IFERROR(INDEX(Party_Ledger!$D$3:$D$100322,MATCH(ROWS($1:22),Party_Ledger!$K$3:$K$100322,0)),"") -> Advance | D33: =IFERROR(INDEX(Party_Ledger!$E$3:$E$100322,MATCH(ROWS($1:22),Party_Ledger!$K$3:$K$100322,0)),"") -> 0 | E33: =IFERROR(INDEX(Party_Ledger!$F$3:$F$100322,MATCH(ROWS($1:22),Party_Ledger!$K$3:$K$100322,0)),"") -> CHI. KHANA 2, WATER | F33: =IFERROR(INDEX(Party_Ledger!$G$3:$G$100322,MATCH(ROWS($1:22),Party_Ledger!$K$3:$K$100322,0)),"") -> 680 | G33: =IFERROR(INDEX(Party_Ledger!$H$3:$H$100322,MATCH(ROWS($1:22),Party_Ledger!$K$3:$K$100322,0)),"") -> 0 | H33: =IF($A33="","",N($F33)-N($G33)) -> 680
A34: =IFERROR(INDEX(Party_Ledger!$A$3:$A$100322, MATCH(ROWS($1:23), Party_Ledger!$K$3:$K$100322, 0)), "") -> 2083/05/10 | B34: =IF(A34="","",IF(ISNUMBER(A34),IFERROR(VLOOKUP(TEXT(A34,"yyyy/mm/dd"),BSAD,2,FALSE),""),IFERROR(VLOOKUP(A34,BSAD,2,FALSE),""))) -> 46260 | C34: =IFERROR(INDEX(Party_Ledger!$D$3:$D$100322,MATCH(ROWS($1:23),Party_Ledger!$K$3:$K$100322,0)),"") -> Advance | D34: =IFERROR(INDEX(Party_Ledger!$E$3:$E$100322,MATCH(ROWS($1:23),Party_Ledger!$K$3:$K$100322,0)),"") -> 0 | E34: =IFERROR(INDEX(Party_Ledger!$F$3:$F$100322,MATCH(ROWS($1:23),Party_Ledger!$K$3:$K$100322,0)),"") -> ADVANCE | F34: =IFERROR(INDEX(Party_Ledger!$G$3:$G$100322,MATCH(ROWS($1:23),Party_Ledger!$K$3:$K$100322,0)),"") -> 7000 | G34: =IFERROR(INDEX(Party_Ledger!$H$3:$H$100322,MATCH(ROWS($1:23),Party_Ledger!$K$3:$K$100322,0)),"") -> 0 | H34: =IF($A34="","",N($F34)-N($G34)) -> 7000
A35: =IFERROR(INDEX(Party_Ledger!$A$3:$A$100322, MATCH(ROWS($1:24), Party_Ledger!$K$3:$K$100322, 0)), "") -> 2083/05/11 | B35: =IF(A35="","",IF(ISNUMBER(A35),IFERROR(VLOOKUP(TEXT(A35,"yyyy/mm/dd"),BSAD,2,FALSE),""),IFERROR(VLOOKUP(A35,BSAD,2,FALSE),""))) -> 46261 | C35: =IFERROR(INDEX(Party_Ledger!$D$3:$D$100322,MATCH(ROWS($1:24),Party_Ledger!$K$3:$K$100322,0)),"") -> Advance | D35: =IFERROR(INDEX(Party_Ledger!$E$3:$E$100322,MATCH(ROWS($1:24),Party_Ledger!$K$3:$K$100322,0)),"") -> 0 | E35: =IFERROR(INDEX(Party_Ledger!$F$3:$F$100322,MATCH(ROWS($1:24),Party_Ledger!$K$3:$K$100322,0)),"") -> WOOD | F35: =IFERROR(INDEX(Party_Ledger!$G$3:$G$100322,MATCH(ROWS($1:24),Party_Ledger!$K$3:$K$100322,0)),"") -> 900 | G35: =IFERROR(INDEX(Party_Ledger!$H$3:$H$100322,MATCH(ROWS($1:24),Party_Ledger!$K$3:$K$100322,0)),"") -> 0 | H35: =IF($A35="","",N($F35)-N($G35)) -> 900
A36: =IFERROR(INDEX(Party_Ledger!$A$3:$A$100322, MATCH(ROWS($1:25), Party_Ledger!$K$3:$K$100322, 0)), "") -> 2083/05/15 | B36: =IF(A36="","",IF(ISNUMBER(A36),IFERROR(VLOOKUP(TEXT(A36,"yyyy/mm/dd"),BSAD,2,FALSE),""),IFERROR(VLOOKUP(A36,BSAD,2,FALSE),""))) -> 46265 | C36: =IFERROR(INDEX(Party_Ledger!$D$3:$D$100322,MATCH(ROWS($1:25),Party_Ledger!$K$3:$K$100322,0)),"") -> Advance | D36: =IFERROR(INDEX(Party_Ledger!$E$3:$E$100322,MATCH(ROWS($1:25),Party_Ledger!$K$3:$K$100322,0)),"") -> 0 | E36: =IFERROR(INDEX(Party_Ledger!$F$3:$F$100322,MATCH(ROWS($1:25),Party_Ledger!$K$3:$K$100322,0)),"") -> ELECTRICITY MAINTINANCE SAIKRIKPA | F36: =IFERROR(INDEX(Party_Ledger!$G$3:$G$100322,MATCH(ROWS($1:25),Party_Ledger!$K$3:$K$100322,0)),"") -> 5500 | G36: =IFERROR(INDEX(Party_Ledger!$H$3:$H$100322,MATCH(ROWS($1:25),Party_Ledger!$K$3:$K$100322,0)),"") -> 0 | H36: =IF($A36="","",N($F36)-N($G36)) -> 5500
A37: =IFERROR(INDEX(Party_Ledger!$A$3:$A$100322, MATCH(ROWS($1:26), Party_Ledger!$K$3:$K$100322, 0)), "") -> 2083/05/17 | B37: =IF(A37="","",IF(ISNUMBER(A37),IFERROR(VLOOKUP(TEXT(A37,"yyyy/mm/dd"),BSAD,2,FALSE),""),IFERROR(VLOOKUP(A37,BSAD,2,FALSE),""))) -> 46267 | C37: =IFERROR(INDEX(Party_Ledger!$D$3:$D$100322,MATCH(ROWS($1:26),Party_Ledger!$K$3:$K$100322,0)),"") -> Advance | D37: =IFERROR(INDEX(Party_Ledger!$E$3:$E$100322,MATCH(ROWS($1:26),Party_Ledger!$K$3:$K$100322,0)),"") -> 0 | E37: =IFERROR(INDEX(Party_Ledger!$F$3:$F$100322,MATCH(ROWS($1:26),Party_Ledger!$K$3:$K$100322,0)),"") -> WOOD | F37: =IFERROR(INDEX(Party_Ledger!$G$3:$G$100322,MATCH(ROWS($1:26),Party_Ledger!$K$3:$K$100322,0)),"") -> 1800 | G37: =IFERROR(INDEX(Party_Ledger!$H$3:$H$100322,MATCH(ROWS($1:26),Party_Ledger!$K$3:$K$100322,0)),"") -> 0 | H37: =IF($A37="","",N($F37)-N($G37)) -> 1800
A38: =IFERROR(INDEX(Party_Ledger!$A$3:$A$100322, MATCH(ROWS($1:27), Party_Ledger!$K$3:$K$100322, 0)), "") -> 2083/05/17 | B38: =IF(A38="","",IF(ISNUMBER(A38),IFERROR(VLOOKUP(TEXT(A38,"yyyy/mm/dd"),BSAD,2,FALSE),""),IFERROR(VLOOKUP(A38,BSAD,2,FALSE),""))) -> 46267 | C38: =IFERROR(INDEX(Party_Ledger!$D$3:$D$100322,MATCH(ROWS($1:27),Party_Ledger!$K$3:$K$100322,0)),"") -> Advance | D38: =IFERROR(INDEX(Party_Ledger!$E$3:$E$100322,MATCH(ROWS($1:27),Party_Ledger!$K$3:$K$100322,0)),"") -> 0 | E38: =IFERROR(INDEX(Party_Ledger!$F$3:$F$100322,MATCH(ROWS($1:27),Party_Ledger!$K$3:$K$100322,0)),"") -> SENSOR MAINTINANCE SAIKRIPA | F38: =IFERROR(INDEX(Party_Ledger!$G$3:$G$100322,MATCH(ROWS($1:27),Party_Ledger!$K$3:$K$100322,0)),"") -> 1500 | G38: =IFERROR(INDEX(Party_Ledger!$H$3:$H$100322,MATCH(ROWS($1:27),Party_Ledger!$K$3:$K$100322,0)),"") -> 0 | H38: =IF($A38="","",N($F38)-N($G38)) -> 1500
A39: =IFERROR(INDEX(Party_Ledger!$A$3:$A$100322, MATCH(ROWS($1:28), Party_Ledger!$K$3:$K$100322, 0)), "") -> 2083/05/17 | B39: =IF(A39="","",IF(ISNUMBER(A39),IFERROR(VLOOKUP(TEXT(A39,"yyyy/mm/dd"),BSAD,2,FALSE),""),IFERROR(VLOOKUP(A39,BSAD,2,FALSE),""))) -> 46267 | C39: =IFERROR(INDEX(Party_Ledger!$D$3:$D$100322,MATCH(ROWS($1:28),Party_Ledger!$K$3:$K$100322,0)),"") -> Advance | D39: =IFERROR(INDEX(Party_Ledger!$E$3:$E$100322,MATCH(ROWS($1:28),Party_Ledger!$K$3:$K$100322,0)),"") -> 0 | E39: =IFERROR(INDEX(Party_Ledger!$F$3:$F$100322,MATCH(ROWS($1:28),Party_Ledger!$K$3:$K$100322,0)),"") -> TRANSPORTATION FOR PIPE WELDING LABOUR | F39: =IFERROR(INDEX(Party_Ledger!$G$3:$G$100322,MATCH(ROWS($1:28),Party_Ledger!$K$3:$K$100322,0)),"") -> 400 | G39: =IFERROR(INDEX(Party_Ledger!$H$3:$H$100322,MATCH(ROWS($1:28),Party_Ledger!$K$3:$K$100322,0)),"") -> 0 | H39: =IF($A39="","",N($F39)-N($G39)) -> 400
A40: =IFERROR(INDEX(Party_Ledger!$A$3:$A$100322, MATCH(ROWS($1:29), Party_Ledger!$K$3:$K$100322, 0)), "") -> 2083/05/17 | B40: =IF(A40="","",IF(ISNUMBER(A40),IFERROR(VLOOKUP(TEXT(A40,"yyyy/mm/dd"),BSAD,2,FALSE),""),IFERROR(VLOOKUP(A40,BSAD,2,FALSE),""))) -> 46267 | C40: =IFERROR(INDEX(Party_Ledger!$D$3:$D$100322,MATCH(ROWS($1:29),Party_Ledger!$K$3:$K$100322,0)),"") -> Advance | D40: =IFERROR(INDEX(Party_Ledger!$E$3:$E$100322,MATCH(ROWS($1:29),Party_Ledger!$K$3:$K$100322,0)),"") -> 0 | E40: =IFERROR(INDEX(Party_Ledger!$F$3:$F$100322,MATCH(ROWS($1:29),Party_Ledger!$K$3:$K$100322,0)),"") -> OIL FOR VEHICLE TO BHAIRAHAWA WELDING | F40: =IFERROR(INDEX(Party_Ledger!$G$3:$G$100322,MATCH(ROWS($1:29),Party_Ledger!$K$3:$K$100322,0)),"") -> 2000 | G40: =IFERROR(INDEX(Party_Ledger!$H$3:$H$100322,MATCH(ROWS($1:29),Party_Ledger!$K$3:$K$100322,0)),"") -> 0 | H40: =IF($A40="","",N($F40)-N($G40)) -> 2000
...

Sheet Party_Ledger
A1: =C7 -> CHHATRABHUMI STORE
A2: Date | B2: AD Date | C2: Party Name | D2: Txn Type | E2: Reference | F2: Description | G2: Debit | H2: Credit | I2: Balance | J2: Remarks | K2: MatchIdx
A3: =Sales_Entry!A3 -> 66915 | B3: =Sales_Entry!B3 -> 46202 | C3: =Sales_Entry!D3 -> NAWA DURGA -317 | D3: Sale | E3: =Sales_Entry!C3 -> OPN-1001 | F3: =Sales_Entry!E3 -> OPENING | G3: =N(Sales_Entry!J3) -> 81953 | H3: 0 | I3: =IF($C3="","",$G3-$H3) -> 81953 | K3: {=IF($C3="","",IF(AND($C3=Party_Statement!$C$5,$B3>=Party_Statement!$C$6,$B3<=Party_Statement!$E$6),SUMPRODUCT(($C$3:$C3=Party_Statement!$C$5)*($B$3:$B3>=Party_Statement!$C$6)*($B$3:$B3<=Party_Statement!$E$6)),""))}
A4: =Sales_Entry!A4 -> 66915 | B4: =Sales_Entry!B4 -> 46202 | C4: =Sales_Entry!D4 -> THE DARBAR PARTY PALACE | D4: Sale | E4: =Sales_Entry!C4 -> OPN-1002 | F4: =Sales_Entry!E4 -> OPENING | G4: =N(Sales_Entry!J4) -> 28322 | H4: 0 | I4: =IF($C4="","",$G4-$H4) -> 28322 | K4: {=IF($C4="","",IF(AND($C4=Party_Statement!$C$5,$B4>=Party_Statement!$C$6,$B4<=Party_Statement!$E$6),SUMPRODUCT(($C$3:$C4=Party_Statement!$C$5)*($B$3:$B4>=Party_Statement!$C$6)*($B$3:$B4<=Party_Statement!$E$6)),""))}
A5: =Sales_Entry!A5 -> 66915 | B5: =Sales_Entry!B5 -> 46202 | C5: =Sales_Entry!D5 -> SRIJANA DAIRY | D5: Sale | E5: =Sales_Entry!C5 -> OPN-1003 | F5: =Sales_Entry!E5 -> OPENING | G5: =N(Sales_Entry!J5) -> 6950 | H5: 0 | I5: =IF($C5="","",$G5-$H5) -> 6950 | K5: {=IF($C5="","",IF(AND($C5=Party_Statement!$C$5,$B5>=Party_Statement!$C$6,$B5<=Party_Statement!$E$6),SUMPRODUCT(($C$3:$C5=Party_Statement!$C$5)*($B$3:$B5>=Party_Statement!$C$6)*($B$3:$B5<=Party_Statement!$E$6)),""))}
A6: =Sales_Entry!A6 -> 66915 | B6: =Sales_Entry!B6 -> 46202 | C6: =Sales_Entry!D6 -> SOBHA BHATTARAI | D6: Sale | E6: =Sales_Entry!C6 -> OPN-1004 | F6: =Sales_Entry!E6 -> OPENING | G6: =N(Sales_Entry!J6) -> 3400 | H6: 0 | I6: =IF($C6="","",$G6-$H6) -> 3400 | K6: {=IF($C6="","",IF(AND($C6=Party_Statement!$C$5,$B6>=Party_Statement!$C$6,$B6<=Party_Statement!$E$6),SUMPRODUCT(($C$3:$C6=Party_Statement!$C$5)*($B$3:$B6>=Party_Statement!$C$6)*($B$3:$B6<=Party_Statement!$E$6)),""))}
A7: =Sales_Entry!A7 -> 66915 | B7: =Sales_Entry!B7 -> 46202 | C7: =Sales_Entry!D7 -> CHHATRABHUMI STORE | D7: Sale | E7: =Sales_Entry!C7 -> OPN-1005 | F7: =Sales_Entry!E7 -> OPENING | G7: =N(Sales_Entry!J7) -> 44495 | H7: 0 | I7: =IF($C7="","",$G7-$H7) -> 44495 | K7: {=IF($C7="","",IF(AND($C7=Party_Statement!$C$5,$B7>=Party_Statement!$C$6,$B7<=Party_Statement!$E$6),SUMPRODUCT(($C$3:$C7=Party_Statement!$C$5)*($B$3:$B7>=Party_Statement!$C$6)*($B$3:$B7<=Party_Statement!$E$6)),""))}
A8: =Sales_Entry!A8 -> 66915 | B8: =Sales_Entry!B8 -> 46202 | C8: =Sales_Entry!D8 -> AAMOSH KIRANA | D8: Sale | E8: =Sales_Entry!C8 -> OPN-1006 | F8: =Sales_Entry!E8 -> OPENING | G8: =N(Sales_Entry!J8) -> 208022 | H8: 0 | I8: =IF($C8="","",$G8-$H8) -> 208022 | K8: {=IF($C8="","",IF(AND($C8=Party_Statement!$C$5,$B8>=Party_Statement!$C$6,$B8<=Party_Statement!$E$6),SUMPRODUCT(($C$3:$C8=Party_Statement!$C$5)*($B$3:$B8>=Party_Statement!$C$6)*($B$3:$B8<=Party_Statement!$E$6)),""))}
A9: =Sales_Entry!A9 -> 66915 | B9: =Sales_Entry!B9 -> 46202 | C9: =Sales_Entry!D9 -> ORGANIC TARKALI | D9: Sale | E9: =Sales_Entry!C9 -> OPN-1007 | F9: =Sales_Entry!E9 -> OPENING | G9: =N(Sales_Entry!J9) -> 9310 | H9: 0 | I9: =IF($C9="","",$G9-$H9) -> 9310 | K9: {=IF($C9="","",IF(AND($C9=Party_Statement!$C$5,$B9>=Party_Statement!$C$6,$B9<=Party_Statement!$E$6),SUMPRODUCT(($C$3:$C9=Party_Statement!$C$5)*($B$3:$B9>=Party_Statement!$C$6)*($B$3:$B9<=Party_Statement!$E$6)),""))}
A10: =Sales_Entry!A10 -> 66915 | B10: =Sales_Entry!B10 -> 46202 | C10: =Sales_Entry!D10 -> SHARMA DAI | D10: Sale | E10: =Sales_Entry!C10 -> OPN-1008 | F10: =Sales_Entry!E10 -> OPENING | G10: =N(Sales_Entry!J10) -> 39602 | H10: 0 | I10: =IF($C10="","",$G10-$H10) -> 39602 | K10: {=IF($C10="","",IF(AND($C10=Party_Statement!$C$5,$B10>=Party_Statement!$C$6,$B10<=Party_Statement!$E$6),SUMPRODUCT(($C$3:$C10=Party_Statement!$C$5)*($B$3:$B10>=Party_Statement!$C$6)*($B$3:$B10<=Party_Statement!$E$6)),""))}
A11: =Sales_Entry!A11 -> 66915 | B11: =Sales_Entry!B11 -> 46202 | C11: =Sales_Entry!D11 -> GANGA NEUPANE | D11: Sale | E11: =Sales_Entry!C11 -> OPN-1009 | F11: =Sales_Entry!E11 -> OPENING | G11: =N(Sales_Entry!J11) -> 14507 | H11: 0 | I11: =IF($C11="","",$G11-$H11) -> 14507 | K11: {=IF($C11="","",IF(AND($C11=Party_Statement!$C$5,$B11>=Party_Statement!$C$6,$B11<=Party_Statement!$E$6),SUMPRODUCT(($C$3:$C11=Party_Statement!$C$5)*($B$3:$B11>=Party_Statement!$C$6)*($B$3:$B11<=Party_Statement!$E$6)),""))}
A12: =Sales_Entry!A12 -> 66915 | B12: =Sales_Entry!B12 -> 46202 | C12: =Sales_Entry!D12 -> GIRI KIRANA | D12: Sale | E12: =Sales_Entry!C12 -> OPN-1010 | F12: =Sales_Entry!E12 -> OPENING | G12: =N(Sales_Entry!J12) -> 2550 | H12: 0 | I12: =IF($C12="","",$G12-$H12) -> 2550 | K12: {=IF($C12="","",IF(AND($C12=Party_Statement!$C$5,$B12>=Party_Statement!$C$6,$B12<=Party_Statement!$E$6),SUMPRODUCT(($C$3:$C12=Party_Statement!$C$5)*($B$3:$B12>=Party_Statement!$C$6)*($B$3:$B12<=Party_Statement!$E$6)),""))}
A13: =Sales_Entry!A13 -> 66915 | B13: =Sales_Entry!B13 -> 46202 | C13: =Sales_Entry!D13 -> NAR BAHADUR RANA | D13: Sale | E13: =Sales_Entry!C13 -> OPN-1011 | F13: =Sales_Entry!E13 -> OPENING | G13: =N(Sales_Entry!J13) -> 8117.5 | H13: 0 | I13: =IF($C13="","",$G13-$H13) -> 8117.5 | K13: {=IF($C13="","",IF(AND($C13=Party_Statement!$C$5,$B13>=Party_Statement!$C$6,$B13<=Party_Statement!$E$6),SUMPRODUCT(($C$3:$C13=Party_Statement!$C$5)*($B$3:$B13>=Party_Statement!$C$6)*($B$3:$B13<=Party_Statement!$E$6)),""))}
A14: =Sales_Entry!A14 -> 66915 | B14: =Sales_Entry!B14 -> 46202 | C14: =Sales_Entry!D14 -> DIPAK NEPAL | D14: Sale | E14: =Sales_Entry!C14 -> OPN-1012 | F14: =Sales_Entry!E14 -> OPENING | G14: =N(Sales_Entry!J14) -> 2750 | H14: 0 | I14: =IF($C14="","",$G14-$H14) -> 2750 | K14: {=IF($C14="","",IF(AND($C14=Party_Statement!$C$5,$B14>=Party_Statement!$C$6,$B14<=Party_Statement!$E$6),SUMPRODUCT(($C$3:$C14=Party_Statement!$C$5)*($B$3:$B14>=Party_Statement!$C$6)*($B$3:$B14<=Party_Statement!$E$6)),""))}
... A1853: =Sales_Entry!A1853 -> 0 | B1853: =Sales_Entry!B1853 | C1853: =Sales_Entry!D1853 -> 0 | D1853: Sale | E1853: =Sales_Entry!C1853 -> 0 | F1853: =Sales_Entry!E1853 -> 0 | G1853: =N(Sales_Entry!J1853) -> 0 | H1853: 0 | I1853: =IF($C1853="","",$G1853-$H1853) -> 0 | K1853: {=IF($C1853="","",IF(AND($C1853=Party_Statement!$C$5,$B1853>=Party_Statement!$C$6,$B1853<=Party_Statement!$E$6),SUMPRODUCT(($C$3:$C1853=Party_Statement!$C$5)*($B$3:$B1853>=Party_Statement!$C$6)*($B$3:$B1853<=Party_Statement!$E$6)),""))}
K1854: {=IF($C1854="","",IF(AND($C1854=Party_Statement!$C$5,$B1854>=Party_Statement!$C$6,$B1854<=Party_Statement!$E$6),SUMPRODUCT(($C$3:$C1854=Party_Statement!$C$5)*($B$3:$B1854>=Party_Statement!$C$6)*($B$3:$B1854<=Party_Statement!$E$6)),""))}
K1855: {=IF($C1855="","",IF(AND($C1855=Party_Statement!$C$5,$B1855>=Party_Statement!$C$6,$B1855<=Party_Statement!$E$6),SUMPRODUCT(($C$3:$C1855=Party_Statement!$C$5)*($B$3:$B1855>=Party_Statement!$C$6)*($B$3:$B1855<=Party_Statement!$E$6)),""))}
A1856: # | B1856: # | C1856: # | D1856: # | E1856: # | F1856: # | G1856: # | H1856: # | I1856: # | J1856: # | K1856: {=IF($C1856="","",IF(AND($C1856=Party_Statement!$C$5,$B1856>=Party_Statement!$C$6,$B1856<=Party_Statement!$E$6),SUMPRODUCT(($C$3:$C1856=Party_Statement!$C$5)*($B$3:$B1856>=Party_Statement!$C$6)*($B$3:$B1856<=Party_Statement!$E$6)),""))}
K1857: {=IF($C1857="","",IF(AND($C1857=Party_Statement!$C$5,$B1857>=Party_Statement!$C$6,$B1857<=Party_Statement!$E$6),SUMPRODUCT(($C$3:$C1857=Party_Statement!$C$5)*($B$3:$B1857>=Party_Statement!$C$6)*($B$3:$B1857<=Party_Statement!$E$6)),""))}
A1858: =Purchase_Entry!A3 -> 2083/03/15 | B1858: =Purchase_Entry!B3 -> 46202 | C1858: =Purchase_Entry!D3 -> MUKTESHWOR ENTERPRISES | D1858: Purchase | E1858: =Purchase_Entry!C3 -> OPN2001 | F1858: =Purchase_Entry!F3 -> OPENING | G1858: 0 | H1858: =N(Purchase_Entry!P3) -> 69018 | I1858: =IF($C1858="","",IF($C1858=$C589,$I589+$G1858-$H1858,$G1858-$H1858)) -> -69018 | K1858: {=IF($C1858="","",IF(AND($C1858=Party_Statement!$C$5,$B1858>=Party_Statement!$C$6,$B1858<=Party_Statement!$E$6),SUMPRODUCT(($C$3:$C1858=Party_Statement!$C$5)*($B$3:$B1858>=Party_Statement!$C$6)*($B$3:$B1858<=Party_Statement!$E$6)),""))}
A1859: =Purchase_Entry!A4 -> 2083/03/32 | B1859: =Purchase_Entry!B4 -> 46219 | C1859: =Purchase_Entry!D4 -> MUKTESHWOR ENTERPRISES | D1859: Purchase | E1859: =Purchase_Entry!C4 -> BILL-0809 | F1859: =Purchase_Entry!F4 -> DISSEL | G1859: 0 | H1859: =N(Purchase_Entry!P4) -> 23295 | I1859: =IF($C1859="","",IF($C1859=$C590,$I590+$G1859-$H1859,$G1859-$H1859)) -> -23295 | K1859: {=IF($C1859="","",IF(AND($C1859=Party_Statement!$C$5,$B1859>=Party_Statement!$C$6,$B1859<=Party_Statement!$E$6),SUMPRODUCT(($C$3:$C1859=Party_Statement!$C$5)*($B$3:$B1859>=Party_Statement!$C$6)*($B$3:$B1859<=Party_Statement!$E$6)),""))}
A1860: =Purchase_Entry!A5 -> 2083/04/31 | B1860: =Purchase_Entry!B5 -> 46250 | C1860: =Purchase_Entry!D5 -> MUKTESHWOR ENTERPRISES | D1860: Purchase | E1860: =Purchase_Entry!C5 -> BILL-0079 | F1860: =Purchase_Entry!F5 -> DISSEL | G1860: 0 | H1860: =N(Purchase_Entry!P5) -> 50715 | I1860: =IF($C1860="","",IF($C1860=$C591,$I591+$G1860-$H1860,$G1860-$H1860)) -> -50715 | K1860: {=IF($C1860="","",IF(AND($C1860=Party_Statement!$C$5,$B1860>=Party_Statement!$C$6,$B1860<=Party_Statement!$E$6),SUMPRODUCT(($C$3:$C1860=Party_Statement!$C$5)*($B$3:$B1860>=Party_Statement!$C$6)*($B$3:$B1860<=Party_Statement!$E$6)),""))}
A1861: =Purchase_Entry!A6 -> 2083/03/15 | B1861: =Purchase_Entry!B6 -> 46202 | C1861: =Purchase_Entry!D6 -> MODERN AGRO -315 | D1861: Purchase | E1861: =Purchase_Entry!C6 -> OPN2002 | F1861: =Purchase_Entry!F6 -> OPENING | G1861: 0 | H1861: =N(Purchase_Entry!P6) -> 172184 | I1861: =IF($C1861="","",IF($C1861=$C592,$I592+$G1861-$H1861,$G1861-$H1861)) -> -172184 | K1861: {=IF($C1861="","",IF(AND($C1861=Party_Statement!$C$5,$B1861>=Party_Statement!$C$6,$B1861<=Party_Statement!$E$6),SUMPRODUCT(($C$3:$C1861=Party_Statement!$C$5)*($B$3:$B1861>=Party_Statement!$C$6)*($B$3:$B1861<=Party_Statement!$E$6)),""))}
A1862: =Purchase_Entry!A7 -> 2083/03/15 | B1862: =Purchase_Entry!B7 -> 46202 | C1862: =Purchase_Entry!D7 -> LUSCAN | D1862: Purchase | E1862: =Purchase_Entry!C7 -> OPN2003 | F1862: =Purchase_Entry!F7 -> OPENING | G1862: 0 | H1862: =N(Purchase_Entry!P7) -> 278851 | I1862: =IF($C1862="","",IF($C1862=$C593,$I593+$G1862-$H1862,$G1862-$H1862)) -> -278851 | K1862: {=IF($C1862="","",IF(AND($C1862=Party_Statement!$C$5,$B1862>=Party_Statement!$C$6,$B1862<=Party_Statement!$E$6),SUMPRODUCT(($C$3:$C1862=Party_Statement!$C$5)*($B$3:$B1862>=Party_Statement!$C$6)*($B$3:$B1862<=Party_Statement!$E$6)),""))}
A1863: =Purchase_Entry!A8 -> 2083/03/15 | B1863: =Purchase_Entry!B8 -> 46202 | C1863: =Purchase_Entry!D8 -> PRARAMBHA DAIRY SUPPLIERS | D1863: Purchase | E1863: =Purchase_Entry!C8 -> OPN2004 | F1863: =Purchase_Entry!F8 -> OPENING | G1863: 0 | H1863: =N(Purchase_Entry!P8) -> 11932 | I1863: =IF($C1863="","",IF($C1863=$C594,$I594+$G1863-$H1863,$G1863-$H1863)) -> -11932 | K1863: {=IF($C1863="","",IF(AND($C1863=Party_Statement!$C$5,$B1863>=Party_Statement!$C$6,$B1863<=Party_Statement!$E$6),SUMPRODUCT(($C$3:$C1863=Party_Statement!$C$5)*($B$3:$B1863>=Party_Statement!$C$6)*($B$3:$B1863<=Party_Statement!$E$6)),""))}
A1864: =Purchase_Entry!A9 -> 66916 | B1864: =Purchase_Entry!B9 -> 46203 | C1864: =Purchase_Entry!D9 -> BASUDEV DAIRY 316 | D1864: Purchase | E1864: =Purchase_Entry!C9 -> BILL-5006 | F1864: =Purchase_Entry!F9 -> Buffalo Milk | G1864: 0 | H1864: =N(Purchase_Entry!P9) -> 21948 | I1864: =IF($C1864="","",IF($C1864=$C595,$I595+$G1864-$H1864,$G1864-$H1864)) -> -21948 | K1864: {=IF($C1864="","",IF(AND($C1864=Party_Statement!$C$5,$B1864>=Party_Statement!$C$6,$B1864<=Party_Statement!$E$6),SUMPRODUCT(($C$3:$C1864=Party_Statement!$C$5)*($B$3:$B1864>=Party_Statement!$C$6)*($B$3:$B1864<=Party_Statement!$E$6)),""))}
A1865: =Purchase_Entry!A10 -> 66918 | B1865: =Purchase_Entry!B10 -> 46205 | C1865: =Purchase_Entry!D10 -> BASUDEV DAIRY 316 | D1865: Purchase | E1865: =Purchase_Entry!C10 -> BILL-5020 | F1865: =Purchase_Entry!F10 -> Buffalo Milk | G1865: 0 | H1865: =N(Purchase_Entry!P10) -> 23436 | I1865: =IF($C1865="","",IF($C1865=$C596,$I596+$G1865-$H1865,$G1865-$H1865)) -> -23436 | K1865: {=IF($C1865="","",IF(AND($C1865=Party_Statement!$C$5,$B1865>=Party_Statement!$C$6,$B1865<=Party_Statement!$E$6),SUMPRODUCT(($C$3:$C1865=Party_Statement!$C$5)*($B$3:$B1865>=Party_Statement!$C$6)*($B$3:$B1865<=Party_Statement!$E$6)),""))}
A1866: =Purchase_Entry!A11 -> 66920 | B1866: =Purchase_Entry!B11 -> 46207 | C1866: =Purchase_Entry!D11 -> BASUDEV DAIRY 316 | D1866: Purchase | E1866: =Purchase_Entry!C11 -> BILL-5034 | F1866: =Purchase_Entry!F11 -> Buffalo Milk | G1866: 0 | H1866: =N(Purchase_Entry!P11) -> 24180 | I1866: =IF($C1866="","",IF($C1866=$C597,$I597+$G1866-$H1866,$G1866-$H1866)) -> -24180 | K1866: {=IF($C1866="","",IF(AND($C1866=Party_Statement!$C$5,$B1866>=Party_Statement!$C$6,$B1866<=Party_Statement!$E$6),SUMPRODUCT(($C$3:$C1866=Party_Statement!$C$5)*($B$3:$B1866>=Party_Statement!$C$6)*($B$3:$B1866<=Party_Statement!$E$6)),""))}
A1867: =Purchase_Entry!A12 -> 66922 | B1867: =Purchase_Entry!B12 -> 46209 | C1867: =Purchase_Entry!D12 -> BASUDEV DAIRY 316 | D1867: Purchase | E1867: =Purchase_Entry!C12 -> BILL-5048 | F1867: =Purchase_Entry!F12 -> Buffalo Milk | G1867: 0 | H1867: =N(Purchase_Entry!P12) -> 23064 | I1867: =IF($C1867="","",IF($C1867=$C598,$I598+$G1867-$H1867,$G1867-$H1867)) -> -23064 | K1867: {=IF($C1867="","",IF(AND($C1867=Party_Statement!$C$5,$B1867>=Party_Statement!$C$6,$B1867<=Party_Statement!$E$6),SUMPRODUCT(($C$3:$C1867=Party_Statement!$C$5)*($B$3:$B1867>=Party_Statement!$C$6)*($B$3:$B1867<=Party_Statement!$E$6)),""))}
A1868: =Purchase_Entry!A13 -> 66924 | B1868: =Purchase_Entry!B13 -> 46211 | C1868: =Purchase_Entry!D13 -> BASUDEV DAIRY 316 | D1868: Purchase | E1868: =Purchase_Entry!C13 -> BILL-5062 | F1868: =Purchase_Entry!F13 -> Buffalo Milk | G1868: 0 | H1868: =N(Purchase_Entry!P13) -> 23436 | I1868: =IF($C1868="","",IF($C1868=$C599,$I599+$G1868-$H1868,$G1868-$H1868)) -> -23436 | K1868: {=IF($C1868="","",IF(AND($C1868=Party_Statement!$C$5,$B1868>=Party_Statement!$C$6,$B1868<=Party_Statement!$E$6),SUMPRODUCT(($C$3:$C1868=Party_Statement!$C$5)*($B$3:$B1868>=Party_Statement!$C$6)*($B$3:$B1868<=Party_Statement!$E$6)),""))}
A1869: =Purchase_Entry!A14 -> 66926 | B1869: =Purchase_Entry!B14 -> 46213 | C1869: =Purchase_Entry!D14 -> BASUDEV DAIRY 316 | D1869: Purchase | E1869: =Purchase_Entry!C14 -> BILL-5076 | F1869: =Purchase_Entry!F14 -> Buffalo Milk | G1869: 0 | H1869: =N(Purchase_Entry!P14) -> 23436 | I1869: =IF($C1869="","",IF($C1869=$C600,$I600+$G1869-$H1869,$G1869-$H1869)) -> -23436 | K1869: {=IF($C1869="","",IF(AND($C1869=Party_Statement!$C$5,$B1869>=Party_Statement!$C$6,$B1869<=Party_Statement!$E$6),SUMPRODUCT(($C$3:$C1869=Party_Statement!$C$5)*($B$3:$B1869>=Party_Statement!$C$6)*($B$3:$B1869<=Party_Statement!$E$6)),""))}
... A1898: =Purchase_Entry!A43 -> 66982 | B1898: =Purchase_Entry!B43 -> 46271 | C1898: =Purchase_Entry!D43 -> BASUDEV DAIRY 316 | D1898: Purchase | E1898: =Purchase_Entry!C43 -> BILL-5152 | F1898: =Purchase_Entry!F43 -> Buffalo Milk | G1898: 0 | H1898: =N(Purchase_Entry!P43) -> 31806 | I1898: =IF($C1898="","",IF($C1898=$C629,$I629+$G1898-$H1898,$G1898-$H1898)) -> -31806 | K1898: {=IF($C1898="","",IF(AND($C1898=Party_Statement!$C$5,$B1898>=Party_Statement!$C$6,$B1898<=Party_Statement!$E$6),SUMPRODUCT(($C$3:$C1898=Party_Statement!$C$5)*($B$3:$B1898>=Party_Statement!$C$6)*($B$3:$B1898<=Party_Statement!$E$6)),""))}
A1899: =Purchase_Entry!A49 -> 66926 | B1899: =Purchase_Entry!B49 -> 46213 | C1899: =Purchase_Entry!D49 -> BODESH 310 | D1899: Purchase | E1899: =Purchase_Entry!C49 -> BILL-5078 | F1899: =Purchase_Entry!F49 -> Buffalo Milk | G1899: 0 | H1899: =N(Purchase_Entry!P49) -> 3000 | I1899: =IF($C1899="","",IF($C1899=$C630,$I630+$G1899-$H1899,$G1899-$H1899)) -> -3000 | K1899: {=IF($C1899="","",IF(AND($C1899=Party_Statement!$C$5,$B1899>=Party_Statement!$C$6,$B1899<=Party_Statement!$E$6),SUMPRODUCT(($C$3:$C1899=Party_Statement!$C$5)*($B$3:$B1899>=Party_Statement!$C$6)*($B$3:$B1899<=Party_Statement!$E$6)),""))}
A1900: =Purchase_Entry!A50 -> 66927 | B1900: =Purchase_Entry!B50 -> 46214 | C1900: =Purchase_Entry!D50 -> BODESH 310 | D1900: Purchase | E1900: =Purchase_Entry!C50 -> BILL-5086 | F1900: =Purchase_Entry!F50 -> Buffalo Milk | G1900: 0 | H1900: =N(Purchase_Entry!P50) -> 9000 | I1900: =IF($C1900="","",IF($C1900=$C631,$I631+$G1900-$H1900,$G1900-$H1900)) -> -9000 | K1900: {=IF($C1900="","",IF(AND($C1900=Party_Statement!$C$5,$B1900>=Party_Statement!$C$6,$B1900<=Party_Statement!$E$6),SUMPRODUCT(($C$3:$C1900=Party_Statement!$C$5)*($B$3:$B1900>=Party_Statement!$C$6)*($B$3:$B1900<=Party_Statement!$E$6)),""))}
A1901: =Purchase_Entry!A51 -> 66928 | B1901: =Purchase_Entry!B51 -> 46215 | C1901: =Purchase_Entry!D51 -> BODESH 310 | D1901: Purchase | E1901: =Purchase_Entry!C51 -> BILL-5094 | F1901: =Purchase_Entry!F51 -> Buffalo Milk | G1901: 0 | H1901: =N(Purchase_Entry!P51) -> 9000 | I1901: =IF($C1901="","",IF($C1901=$C632,$I632+$G1901-$H1901,$G1901-$H1901)) -> -9000 | K1901: {=IF($C1901="","",IF(AND($C1901=Party_Statement!$C$5,$B1901>=Party_Statement!$C$6,$B1901<=Party_Statement!$E$6),SUMPRODUCT(($C$3:$C1901=Party_Statement!$C$5)*($B$3:$B1901>=Party_Statement!$C$6)*($B$3:$B1901<=Party_Statement!$E$6)),""))}
A1902: =Purchase_Entry!A52 -> 66929 | B1902: =Purchase_Entry!B52 -> 46216 | C1902: =Purchase_Entry!D52 -> BODESH 310 | D1902: Purchase | E1902: =Purchase_Entry!C52 -> BILL-5102 | F1902: =Purchase_Entry!F52 -> Buffalo Milk | G1902: 0 | H1902: =N(Purchase_Entry!P52) -> 11250 | I1902: =IF($C1902="","",IF($C1902=$C633,$I633+$G1902-$H1902,$G1902-$H1902)) -> -11250 | K1902: {=IF($C1902="","",IF(AND($C1902=Party_Statement!$C$5,$B1902>=Party_Statement!$C$6,$B1902<=Party_Statement!$E$6),SUMPRODUCT(($C$3:$C1902=Party_Statement!$C$5)*($B$3:$B1902>=Party_Statement!$C$6)*($B$3:$B1902<=Party_Statement!$E$6)),""))}
A1903: =Purchase_Entry!A53 -> 66930 | B1903: =Purchase_Entry!B53 -> 46217 | C1903: =Purchase_Entry!D53 -> BODESH 310 | D1903: Purchase | E1903: =Purchase_Entry!C53 -> BILL-5110 | F1903: =Purchase_Entry!F53 -> Buffalo Milk | G1903: 0 | H1903: =N(Purchase_Entry!P53) -> 8250 | I1903: =IF($C1903="","",IF($C1903=$C634,$I634+$G1903-$H1903,$G1903-$H1903)) -> -8250 | K1903: {=IF($C1903="","",IF(AND($C1903=Party_Statement!$C$5,$B1903>=Party_Statement!$C$6,$B1903<=Party_Statement!$E$6),SUMPRODUCT(($C$3:$C1903=Party_Statement!$C$5)*($B$3:$B1903>=Party_Statement!$C$6)*($B$3:$B1903<=Party_Statement!$E$6)),""))}
A1904: =Purchase_Entry!A54 -> 66931 | B1904: =Purchase_Entry!B54 -> 46218 | C1904: =Purchase_Entry!D54 -> BODESH 310 | D1904: Purchase | E1904: =Purchase_Entry!C54 -> BILL-5118 | F1904: =Purchase_Entry!F54 -> Buffalo Milk | G1904: 0 | H1904: =N(Purchase_Entry!P54) -> 3000 | I1904: =IF($C1904="","",IF($C1904=$C635,$I635+$G1904-$H1904,$G1904-$H1904)) -> -3000 | K1904: {=IF($C1904="","",IF(AND($C1904=Party_Statement!$C$5,$B1904>=Party_Statement!$C$6,$B1904<=Party_Statement!$E$6),SUMPRODUCT(($C$3:$C1904=Party_Statement!$C$5)*($B$3:$B1904>=Party_Statement!$C$6)*($B$3:$B1904<=Party_Statement!$E$6)),""))}
A1905: =Purchase_Entry!A55 -> 2083/03/32 | B1905: =Purchase_Entry!B55 -> 46219 | C1905: =Purchase_Entry!D55 -> BODESH 310 | D1905: Purchase | E1905: =Purchase_Entry!C55 -> BILL-5126 | F1905: =Purchase_Entry!F55 -> Buffalo Milk | G1905: 0 | H1905: =N(Purchase_Entry!P55) -> 5250 | I1905: =IF($C1905="","",IF($C1905=$C636,$I636+$G1905-$H1905,$G1905-$H1905)) -> -5250 | K1905: {=IF($C1905="","",IF(AND($C1905=Party_Statement!$C$5,$B1905>=Party_Statement!$C$6,$B1905<=Party_Statement!$E$6),SUMPRODUCT(($C$3:$C1905=Party_Statement!$C$5)*($B$3:$B1905>=Party_Statement!$C$6)*($B$3:$B1905<=Party_Statement!$E$6)),""))}
A1906: =Purchase_Entry!A56 -> 66933 | B1906: =Purchase_Entry!B56 -> 46221 | C1906: =Purchase_Entry!D56 -> BODESH 310 | D1906: Purchase | E1906: =Purchase_Entry!C56 -> BILL-5140 | F1906: =Purchase_Entry!F56 -> Buffalo Milk | G1906: 0 | H1906: =N(Purchase_Entry!P56) -> 5250 | I1906: =IF($C1906="","",IF($C1906=$C637,$I637+$G1906-$H1906,$G1906-$H1906)) -> -5250 | K1906: {=IF($C1906="","",IF(AND($C1906=Party_Statement!$C$5,$B1906>=Party_Statement!$C$6,$B1906<=Party_Statement!$E$6),SUMPRODUCT(($C$3:$C1906=Party_Statement!$C$5)*($B$3:$B1906>=Party_Statement!$C$6)*($B$3:$B1906<=Party_Statement!$E$6)),""))}
...

Sheet Sales_Entry
A1: =D33 -> CHHATRABHUMI STORE
A2: Date | B2: AD Date | C2: Invoice No | D2: Party Name | E2: Product | F2: Quantity | G2: Rate | H2: Amount | I2: Discount % | J2: Net Amount | K2: Payment Mode | L2: Status | M2: Remarks
A3: 66915 | B3: =IF(A3="","",IF(ISNUMBER(A3),IFERROR(VLOOKUP(TEXT(A3,"yyyy/mm/dd"),BSAD,2,FALSE),""),IFERROR(VLOOKUP(A3,BSAD,2,FALSE),""))) -> 46202 | C3: OPN-1001 | D3: NAWA DURGA -317 | E3: OPENING | F3: 1 | G3: 81953 | H3: =IF($F3="","",$F3*$G3) -> 81953 | I3: 0 | J3: =IF($F3="","",$H3*(1-$I3/100)) -> 81953 | K3: Credit | L3: Unpaid
A4: 66915 | B4: =IF(A4="","",IF(ISNUMBER(A4),IFERROR(VLOOKUP(TEXT(A4,"yyyy/mm/dd"),BSAD,2,FALSE),""),IFERROR(VLOOKUP(A4,BSAD,2,FALSE),""))) -> 46202 | C4: OPN-1002 | D4: THE DARBAR PARTY PALACE | E4: OPENING | F4: 1 | G4: 28322 | H4: =IF($F4="","",$F4*$G4) -> 28322 | I4: 0 | J4: =IF($F4="","",$H4*(1-$I4/100)) -> 28322 | K4: Credit | L4: Unpaid
A5: 66915 | B5: =IF(A5="","",IF(ISNUMBER(A5),IFERROR(VLOOKUP(TEXT(A5,"yyyy/mm/dd"),BSAD,2,FALSE),""),IFERROR(VLOOKUP(A5,BSAD,2,FALSE),""))) -> 46202 | C5: OPN-1003 | D5: SRIJANA DAIRY | E5: OPENING | F5: 1 | G5: 6950 | H5: =IF($F5="","",$F5*$G5) -> 6950 | I5: 0 | J5: =IF($F5="","",$H5*(1-$I5/100)) -> 6950 | K5: Credit | L5: Unpaid
A6: 66915 | B6: =IF(A6="","",IF(ISNUMBER(A6),IFERROR(VLOOKUP(TEXT(A6,"yyyy/mm/dd"),BSAD,2,FALSE),""),IFERROR(VLOOKUP(A6,BSAD,2,FALSE),""))) -> 46202 | C6: OPN-1004 | D6: SOBHA BHATTARAI | E6: OPENING | F6: 1 | G6: 3400 | H6: =IF($F6="","",$F6*$G6) -> 3400 | I6: 0 | J6: =IF($F6="","",$H6*(1-$I6/100)) -> 3400 | K6: Credit | L6: Unpaid
