Workbook

Sheet Dashboard
A1: 🐄 [Your Dairy Plant Name]
A2: 📊 Accounts Dashboard — Generated 14-Jul-2026 | Version 1.0
A3: =HYPERLINK("#'Daybook'!A1","▶ 📒 Daybook") -> ▶ 📒 Daybook | B3: =HYPERLINK("#'Sales_Entry'!A1","▶ 📝 Sales") -> ▶ 📝 Sales | C3: =HYPERLINK("#'Purchase_Entry'!A1","▶ 📦 Purchases") -> ▶ 📦 Purchases | D3: =HYPERLINK("#'Cash_Collection'!A1","▶ 💵 Collections") -> ▶ 💵 Collections | E3: =HYPERLINK("#'Stock_Master'!A1","▶ 📋 Stock") -> ▶ 📋 Stock | F3: =HYPERLINK("#'Party_Master'!A1","▶ 👥 Parties") -> ▶ 👥 Parties | G3: =HYPERLINK("#'Party_Ledger'!A1","▶ 📊 Ledger") -> ▶ 📊 Ledger | H3: =HYPERLINK("#'Sales_Report'!A1","▶ 📈 Sales Rpt") -> ▶ 📈 Sales Rpt | I3: =HYPERLINK("#'Purchase_Report'!A1","▶ 📉 Purchase Rpt") -> ▶ 📉 Purchase Rpt | J3: =HYPERLINK("#'Stock_Report'!A1","▶ 🗃️ Stock Rpt") -> ▶ 🗃️ Stock Rpt | K3: =HYPERLINK("#'Printable_Invoice'!A1","▶ 🧾 Invoice") -> ▶ 🧾 Invoice | L3: =HYPERLINK("#'Printable_Ledger'!A1","▶ 📜 Statement") -> ▶ 📜 Statement
A5: 💰 MONTHLY SALES | D5: 📦 MONTHLY PURCHASES | G5: 📋 STOCK VALUE | J5: ⚠️ ⚠️ LOW STOCK ITEMS
A6: =SUMIFS(Sales_Entry!J$2:J$5000,Sales_Entry!A$2:A$5000,">="&DATE(YEAR(TODAY()),MONTH(TODAY()),1),Sales_Entry!A$2:A$5000,"<="&EOMONTH(TODAY(),0)) -> 0 | D6: =SUMIFS(Purchase_Entry!N$2:N$5000,Purchase_Entry!A$2:A$5000,">="&DATE(YEAR(TODAY()),MONTH(TODAY()),1),Purchase_Entry!A$2:A$5000,"<="&EOMONTH(TODAY(),0)) -> 46169.094 | G6: =SUMPRODUCT((Stock_Master!F$2:F$5000)*(Stock_Master!H$2:H$5000)) -> 208131 | J6: =COUNTIF(Stock_Master!J$2:J$5000,"Reorder") -> 1
A7: 📤 OUTSTANDING RECEIVABLES | D7: 📥 OUTSTANDING PAYABLES | G7: 👥 TOTAL PARTIES | J7: 💰 DAYBOOK BALANCE
A8: =SUMIFS(Sales_Entry!J$2:J$5000,Sales_Entry!K$2:K$5000,"Unpaid")+SUMIFS(Sales_Entry!J$2:J$5000,Sales_Entry!K$2:K$5000,"Partial") -> 0 | D8: =SUMIFS(Purchase_Entry!N$2:N$5000,Purchase_Entry!P$2:P$5000,"Unpaid")+SUMIFS(Purchase_Entry!N$2:N$5000,Purchase_Entry!P$2:P$5000,"Partial") -> 27877.938 | G8: =COUNTA(Party_Master!A$2:A$5000) -> 9 | J8: =IFERROR(INDEX(Daybook!G$2:G$5000,COUNTA(Daybook!A$2:A$5000)),0) -> 45200
A11: 📈 MONTHLY TREND (Sales vs Purchases)
A12: Month | B12: Sales | C12: Purchases | D12: Net Profit/Loss | E12: Invoice Count | F12: Purchase Count
A13: Jul 2026 | B13: =SUMIFS(Sales_Entry!J$2:J$5000,Sales_Entry!A$2:A$5000,">="&DATE(2026,7,1),Sales_Entry!A$2:A$5000,"<="&DATE(2026,7,31)) -> 0 | C13: =SUMIFS(Purchase_Entry!N$2:N$5000,Purchase_Entry!A$2:A$5000,">="&DATE(2026,7,1),Purchase_Entry!A$2:A$5000,"<="&DATE(2026,7,31)) -> 46169.094 | D13: =B13-C13 -> -46169.094 | E13: =COUNTIFS(Sales_Entry!A$2:A$5000,">="&DATE(2026,7,1),Sales_Entry!A$2:A$5000,"<="&DATE(2026,7,31)) -> 10 | F13: =COUNTIFS(Purchase_Entry!A$2:A$5000,">="&DATE(2026,7,1),Purchase_Entry!A$2:A$5000,"<="&DATE(2026,7,31)) -> 8
A14: Jun 2026 | B14: =SUMIFS(Sales_Entry!J$2:J$5000,Sales_Entry!A$2:A$5000,">="&DATE(2026,6,1),Sales_Entry!A$2:A$5000,"<="&DATE(2026,6,30)) -> 0 | C14: =SUMIFS(Purchase_Entry!N$2:N$5000,Purchase_Entry!A$2:A$5000,">="&DATE(2026,6,1),Purchase_Entry!A$2:A$5000,"<="&DATE(2026,6,30)) -> 0 | D14: =B14-C14 -> 0 | E14: =COUNTIFS(Sales_Entry!A$2:A$5000,">="&DATE(2026,6,1),Sales_Entry!A$2:A$5000,"<="&DATE(2026,6,30)) -> 0 | F14: =COUNTIFS(Purchase_Entry!A$2:A$5000,">="&DATE(2026,6,1),Purchase_Entry!A$2:A$5000,"<="&DATE(2026,6,30)) -> 0
A15: May 2026 | B15: =SUMIFS(Sales_Entry!J$2:J$5000,Sales_Entry!A$2:A$5000,">="&DATE(2026,5,1),Sales_Entry!A$2:A$5000,"<="&DATE(2026,5,31)) -> 0 | C15: =SUMIFS(Purchase_Entry!N$2:N$5000,Purchase_Entry!A$2:A$5000,">="&DATE(2026,5,1),Purchase_Entry!A$2:A$5000,"<="&DATE(2026,5,31)) -> 0 | D15: =B15-C15 -> 0 | E15: =COUNTIFS(Sales_Entry!A$2:A$5000,">="&DATE(2026,5,1),Sales_Entry!A$2:A$5000,"<="&DATE(2026,5,31)) -> 0 | F15: =COUNTIFS(Purchase_Entry!A$2:A$5000,">="&DATE(2026,5,1),Purchase_Entry!A$2:A$5000,"<="&DATE(2026,5,31)) -> 0
A16: Apr 2026 | B16: =SUMIFS(Sales_Entry!J$2:J$5000,Sales_Entry!A$2:A$5000,">="&DATE(2026,4,1),Sales_Entry!A$2:A$5000,"<="&DATE(2026,4,30)) -> 0 | C16: =SUMIFS(Purchase_Entry!N$2:N$5000,Purchase_Entry!A$2:A$5000,">="&DATE(2026,4,1),Purchase_Entry!A$2:A$5000,"<="&DATE(2026,4,30)) -> 0 | D16: =B16-C16 -> 0 | E16: =COUNTIFS(Sales_Entry!A$2:A$5000,">="&DATE(2026,4,1),Sales_Entry!A$2:A$5000,"<="&DATE(2026,4,30)) -> 0 | F16: =COUNTIFS(Purchase_Entry!A$2:A$5000,">="&DATE(2026,4,1),Purchase_Entry!A$2:A$5000,"<="&DATE(2026,4,30)) -> 0
A17: Mar 2026 | B17: =SUMIFS(Sales_Entry!J$2:J$5000,Sales_Entry!A$2:A$5000,">="&DATE(2026,3,1),Sales_Entry!A$2:A$5000,"<="&DATE(2026,3,31)) -> 0 | C17: =SUMIFS(Purchase_Entry!N$2:N$5000,Purchase_Entry!A$2:A$5000,">="&DATE(2026,3,1),Purchase_Entry!A$2:A$5000,"<="&DATE(2026,3,31)) -> 0 | D17: =B17-C17 -> 0 | E17: =COUNTIFS(Sales_Entry!A$2:A$5000,">="&DATE(2026,3,1),Sales_Entry!A$2:A$5000,"<="&DATE(2026,3,31)) -> 0 | F17: =COUNTIFS(Purchase_Entry!A$2:A$5000,">="&DATE(2026,3,1),Purchase_Entry!A$2:A$5000,"<="&DATE(2026,3,31)) -> 0
A18: Feb 2026 | B18: =SUMIFS(Sales_Entry!J$2:J$5000,Sales_Entry!A$2:A$5000,">="&DATE(2026,2,1),Sales_Entry!A$2:A$5000,"<="&DATE(2026,2,28)) -> 0 | C18: =SUMIFS(Purchase_Entry!N$2:N$5000,Purchase_Entry!A$2:A$5000,">="&DATE(2026,2,1),Purchase_Entry!A$2:A$5000,"<="&DATE(2026,2,28)) -> 0 | D18: =B18-C18 -> 0 | E18: =COUNTIFS(Sales_Entry!A$2:A$5000,">="&DATE(2026,2,1),Sales_Entry!A$2:A$5000,"<="&DATE(2026,2,28)) -> 0 | F18: =COUNTIFS(Purchase_Entry!A$2:A$5000,">="&DATE(2026,2,1),Purchase_Entry!A$2:A$5000,"<="&DATE(2026,2,28)) -> 0
A20: 🏢 PARTY BALANCE SUMMARY
A21: Party Name | B21: Type | C21: Opening Balance | D21: Total Debit | E21: Total Credit | F21: Current Balance | G21: Status
A22: [Enter Party 1] | B22: =IFERROR(VLOOKUP(A22,Party_Master!B$2:I$5000,1,FALSE),"") | C22: =IFERROR(VLOOKUP(A22,Party_Master!B$2:I$5000,4,FALSE),0) -> 0 | D22: =SUMIF(Party_Ledger!B$2:B$5000,A22,Party_Ledger!F$2:F$5000) -> 0 | E22: =SUMIF(Party_Ledger!B$2:B$5000,A22,Party_Ledger!G$2:G$5000) -> 0 | F22: =C22+D22-E22 -> 0 | G22: =IF(F22>0,"Receivable",IF(F22<0,"Payable","Settled")) -> Settled
A23: [Enter Party 2] | B23: =IFERROR(VLOOKUP(A23,Party_Master!B$2:I$5000,1,FALSE),"") | C23: =IFERROR(VLOOKUP(A23,Party_Master!B$2:I$5000,4,FALSE),0) -> 0 | D23: =SUMIF(Party_Ledger!B$2:B$5000,A23,Party_Ledger!F$2:F$5000) -> 0 | E23: =SUMIF(Party_Ledger!B$2:B$5000,A23,Party_Ledger!G$2:G$5000) -> 0 | F23: =C23+D23-E23 -> 0 | G23: =IF(F23>0,"Receivable",IF(F23<0,"Payable","Settled")) -> Settled
A24: [Enter Party 3] | B24: =IFERROR(VLOOKUP(A24,Party_Master!B$2:I$5000,1,FALSE),"") | C24: =IFERROR(VLOOKUP(A24,Party_Master!B$2:I$5000,4,FALSE),0) -> 0 | D24: =SUMIF(Party_Ledger!B$2:B$5000,A24,Party_Ledger!F$2:F$5000) -> 0 | E24: =SUMIF(Party_Ledger!B$2:B$5000,A24,Party_Ledger!G$2:G$5000) -> 0 | F24: =C24+D24-E24 -> 0 | G24: =IF(F24>0,"Receivable",IF(F24<0,"Payable","Settled")) -> Settled
A25: [Enter Party 4] | B25: =IFERROR(VLOOKUP(A25,Party_Master!B$2:I$5000,1,FALSE),"") | C25: =IFERROR(VLOOKUP(A25,Party_Master!B$2:I$5000,4,FALSE),0) -> 0 | D25: =SUMIF(Party_Ledger!B$2:B$5000,A25,Party_Ledger!F$2:F$5000) -> 0 | E25: =SUMIF(Party_Ledger!B$2:B$5000,A25,Party_Ledger!G$2:G$5000) -> 0 | F25: =C25+D25-E25 -> 0 | G25: =IF(F25>0,"Receivable",IF(F25<0,"Payable","Settled")) -> Settled
A26: [Enter Party 5] | B26: =IFERROR(VLOOKUP(A26,Party_Master!B$2:I$5000,1,FALSE),"") | C26: =IFERROR(VLOOKUP(A26,Party_Master!B$2:I$5000,4,FALSE),0) -> 0 | D26: =SUMIF(Party_Ledger!B$2:B$5000,A26,Party_Ledger!F$2:F$5000) -> 0 | E26: =SUMIF(Party_Ledger!B$2:B$5000,A26,Party_Ledger!G$2:G$5000) -> 0 | F26: =C26+D26-E26 -> 0 | G26: =IF(F26>0,"Receivable",IF(F26<0,"Payable","Settled")) -> Settled
A27: [Enter Party 6] | B27: =IFERROR(VLOOKUP(A27,Party_Master!B$2:I$5000,1,FALSE),"") | C27: =IFERROR(VLOOKUP(A27,Party_Master!B$2:I$5000,4,FALSE),0) -> 0 | D27: =SUMIF(Party_Ledger!B$2:B$5000,A27,Party_Ledger!F$2:F$5000) -> 0 | E27: =SUMIF(Party_Ledger!B$2:B$5000,A27,Party_Ledger!G$2:G$5000) -> 0 | F27: =C27+D27-E27 -> 0 | G27: =IF(F27>0,"Receivable",IF(F27<0,"Payable","Settled")) -> Settled
A28: [Enter Party 7] | B28: =IFERROR(VLOOKUP(A28,Party_Master!B$2:I$5000,1,FALSE),"") | C28: =IFERROR(VLOOKUP(A28,Party_Master!B$2:I$5000,4,FALSE),0) -> 0 | D28: =SUMIF(Party_Ledger!B$2:B$5000,A28,Party_Ledger!F$2:F$5000) -> 0 | E28: =SUMIF(Party_Ledger!B$2:B$5000,A28,Party_Ledger!G$2:G$5000) -> 0 | F28: =C28+D28-E28 -> 0 | G28: =IF(F28>0,"Receivable",IF(F28<0,"Payable","Settled")) -> Settled
A29: [Enter Party 8] | B29: =IFERROR(VLOOKUP(A29,Party_Master!B$2:I$5000,1,FALSE),"") | C29: =IFERROR(VLOOKUP(A29,Party_Master!B$2:I$5000,4,FALSE),0) -> 0 | D29: =SUMIF(Party_Ledger!B$2:B$5000,A29,Party_Ledger!F$2:F$5000) -> 0 | E29: =SUMIF(Party_Ledger!B$2:B$5000,A29,Party_Ledger!G$2:G$5000) -> 0 | F29: =C29+D29-E29 -> 0 | G29: =IF(F29>0,"Receivable",IF(F29<0,"Payable","Settled")) -> Settled
A31: ⚠️ LOW STOCK ALERTS
A32: Product | B32: Current Stock | C32: Reorder Level | D32: Status
A33: =IFERROR(INDEX(Stock_Master!A$2:A$5000,2),"") -> Cow Milk | B33: =IF(A33="","",INDEX(Stock_Master!F$2:F$5000,2)) -> 595.4 | C33: =IF(A33="","",INDEX(Stock_Master!G$2:G$5000,2)) -> 100 | D33: =IF(A33="","",INDEX(Stock_Master!J$2:J$5000,2)) -> In Stock
A34: =IFERROR(INDEX(Stock_Master!A$2:A$5000,3),"") -> Curd (Dahi) | B34: =IF(A34="","",INDEX(Stock_Master!F$2:F$5000,3)) -> 64.8 | C34: =IF(A34="","",INDEX(Stock_Master!G$2:G$5000,3)) -> 20 | D34: =IF(A34="","",INDEX(Stock_Master!J$2:J$5000,3)) -> In Stock
A35: =IFERROR(INDEX(Stock_Master!A$2:A$5000,4),"") -> Ghee | B35: =IF(A35="","",INDEX(Stock_Master!F$2:F$5000,4)) -> 109.2 | C35: =IF(A35="","",INDEX(Stock_Master!G$2:G$5000,4)) -> 10 | D35: =IF(A35="","",INDEX(Stock_Master!J$2:J$5000,4)) -> In Stock
A36: =IFERROR(INDEX(Stock_Master!A$2:A$5000,5),"") -> Paneer | B36: =IF(A36="","",INDEX(Stock_Master!F$2:F$5000,5)) -> -16.4 | C36: =IF(A36="","",INDEX(Stock_Master!G$2:G$5000,5)) -> 5 | D36: =IF(A36="","",INDEX(Stock_Master!J$2:J$5000,5)) -> Reorder
A37: =IFERROR(INDEX(Stock_Master!A$2:A$5000,6),"") -> Butter | B37: =IF(A37="","",INDEX(Stock_Master!F$2:F$5000,6)) -> 20 | C37: =IF(A37="","",INDEX(Stock_Master!G$2:G$5000,6)) -> 5 | D37: =IF(A37="","",INDEX(Stock_Master!J$2:J$5000,6)) -> In Stock
A38: =IFERROR(INDEX(Stock_Master!A$2:A$5000,7),"") -> Buttermilk | B38: =IF(A38="","",INDEX(Stock_Master!F$2:F$5000,7)) -> 60 | C38: =IF(A38="","",INDEX(Stock_Master!G$2:G$5000,7)) -> 15 | D38: =IF(A38="","",INDEX(Stock_Master!J$2:J$5000,7)) -> In Stock
A39: =IFERROR(INDEX(Stock_Master!A$2:A$5000,8),"") -> Khoya | B39: =IF(A39="","",INDEX(Stock_Master!F$2:F$5000,8)) -> 15 | C39: =IF(A39="","",INDEX(Stock_Master!G$2:G$5000,8)) -> 5 | D39: =IF(A39="","",INDEX(Stock_Master!J$2:J$5000,8)) -> In Stock
A40: =IFERROR(INDEX(Stock_Master!A$2:A$5000,9),"") -> 0 | B40: =IF(A40="","",INDEX(Stock_Master!F$2:F$5000,9)) -> 0 | C40: =IF(A40="","",INDEX(Stock_Master!G$2:G$5000,9)) -> 0 | D40: =IF(A40="","",INDEX(Stock_Master!J$2:J$5000,9)) -> 0
A42: 🕐 RECENT TRANSACTIONS
A43: Date | B43: Type | C43: Party | D43: Invoice/Bill | E43: Amount | F43: Status
A44: =IFERROR(INDEX(Sales_Entry!A$2:A$5000,2),"") -> 46216 | B44: "Sale" | C44: =IFERROR(INDEX(Sales_Entry!C$2:C$5000,2),"") -> Bhatbhateni Supermarket | D44: =IFERROR(INDEX(Sales_Entry!B$2:B$5000,2),"") -> INV-1002 | E44: =IFERROR(INDEX(Sales_Entry!J$2:J$5000,2),"") -> Credit | F44: =IFERROR(INDEX(Sales_Entry!K$2:K$5000,2),"") -> Unpaid
A45: =IFERROR(INDEX(Sales_Entry!A$2:A$5000,3),"") -> 46215 | B45: "Sale" | C45: =IFERROR(INDEX(Sales_Entry!C$2:C$5000,3),"") -> Patan Co-op | D45: =IFERROR(INDEX(Sales_Entry!B$2:B$5000,3),"") -> INV-1003 | E45: =IFERROR(INDEX(Sales_Entry!J$2:J$5000,3),"") -> Bank Transfer | F45: =IFERROR(INDEX(Sales_Entry!K$2:K$5000,3),"") -> Partial
A46: =IFERROR(INDEX(Sales_Entry!A$2:A$5000,4),"") -> 46214 | B46: "Sale" | C46: =IFERROR(INDEX(Sales_Entry!C$2:C$5000,4),"") -> Hotel Annapurna | D46: =IFERROR(INDEX(Sales_Entry!B$2:B$5000,4),"") -> INV-1004 | E46: =IFERROR(INDEX(Sales_Entry!J$2:J$5000,4),"") -> UPI | F46: =IFERROR(INDEX(Sales_Entry!K$2:K$5000,4),"") -> Paid
...

Sheet Daybook
A1: 🐄 [Your Dairy Plant Name]
A2: 📒 Daybook — Daily Debit/Credit Register
A4: Instructions:
A5: Record ALL daily transactions here. Debit = money outflow (expenses, purchases), Credit = money inflow (sales, receipts). Balance updates automatically.
A6: 💡 Sales & Purchase entries can be manually posted here from their respective sheets for a complete audit trail.
A8: Date | B8: Particulars | C8: Voucher Type | D8: Reference No | E8: Debit (Dr) | F8: Credit (Cr) | G8: Balance | H8: Narration
A9: 46082 | B9: Opening Balance | C9: Opening | F9: 50000 | G9: 50000 | H9: Opening cash & bank balance
A10: 46207 | B10: Sharma Dairy Shop | C10: Sale | D10: INV-1001 | F10: 5800 | G10: =G9+IF(F10="",0,F10)-IF(E10="",0,E10) -> 55800 | H10: Sale of milk & products
A11: 46208 | B11: Gurung Dairy Farm | C11: Purchase | D11: BILL-5001 | E11: 15300 | G11: =G10+IF(F11="",0,F11)-IF(E11="",0,E11) -> 40500 | H11: Milk purchase with transport
A12: 46209 | B12: Cash Sales | C12: Sale | D12: CS-001 | F12: 4200 | G12: =G11+IF(F12="",0,F12)-IF(E12="",0,E12) -> 44700 | H12: Counter sales - daily collection
A13: 46210 | B13: Salary | C13: Payment | D13: PAY-001 | E13: 12000 | G13: =G12+IF(F13="",0,F13)-IF(E13="",0,E13) -> 32700 | H13: Monthly staff salary
A14: 46211 | B14: Bhatbhateni Supermarket | C14: Sale | D14: INV-1002 | F14: 8500 | G14: =G13+IF(F14="",0,F14)-IF(E14="",0,E14) -> 41200 | H14: Bulk ghee & paneer supply
A15: 46212 | B15: Transport | C15: Payment | D15: PAY-002 | E15: 2500 | G15: =G14+IF(F15="",0,F15)-IF(E15="",0,E15) -> 38700 | H15: Milk transport charges
A16: 46213 | B16: Sharma Dairy Shop | C16: Receipt | D16: PAY-101 | F16: 10000 | G16: =G15+IF(F16="",0,F16)-IF(E16="",0,E16) -> 48700 | H16: Payment received - bank transfer
A17: 46214 | B17: Electricity | C17: Payment | D17: PAY-003 | E17: 3500 | G17: =G16+IF(F17="",0,F17)-IF(E17="",0,E17) -> 45200 | H17: Monthly electricity bill
A18: 46215 | B18: Fresh Valley Suppliers | C18: Purchase | D18: BILL-5002 | E18: 12500 | G18: =G17+IF(F18="",0,F18)-IF(E18="",0,E18) -> 32700 | H18: Milk purchase - Formula rate
A19: 46216 | B19: Hotel Annapurna | C19: Sale | D19: INV-1003 | F19: 3200 | G19: =G18+IF(F19="",0,F19)-IF(E19="",0,E19) -> 35900 | H19: Ghee & butter supply
C20: TOTALS | E20: =SUM(E9:E19) -> 45800 | F20: =SUM(F9:F19) -> 81700

Sheet Sales_Entry
A1: Date | B1: Invoice No | C1: Party Name | D1: Product | E1: Quantity | F1: Rate | G1: Amount | H1: Discount % | I1: Net Amount | J1: Payment Mode | K1: Status | L1: Remarks
A2: 46217 | B2: INV-1001 | C2: Sharma Dairy Shop | D2: Raw Milk | E2: 5 | F2: 60 | G2: =E2*F2 -> 300 | H2: 0 | I2: =G2-(G2*H2/100) -> 300 | J2: Cash | K2: Paid
A3: 46216 | B3: INV-1002 | C3: Bhatbhateni Supermarket | D3: Cow Milk | E3: 7.8 | F3: 65 | G3: =E3*F3 -> 507 | H3: 2.5 | I3: =G3-(G3*H3/100) -> 494.325 | J3: Credit | K3: Unpaid
A4: 46215 | B4: INV-1003 | C4: Patan Co-op | D4: Curd (Dahi) | E4: 10.6 | F4: 100 | G4: =E4*F4 -> 1060 | H4: 2.5 | I4: =G4-(G4*H4/100) -> 1033.5 | J4: Bank Transfer | K4: Partial
A5: 46214 | B5: INV-1004 | C5: Hotel Annapurna | D5: Ghee | E5: 13.4 | F5: 650 | G5: =E5*F5 -> 8710 | H5: 2.5 | I5: =G5-(G5*H5/100) -> 8492.25 | J5: UPI | K5: Paid
A6: 46213 | B6: INV-1005 | C6: Khadgi Sweets | D6: Paneer | E6: 16.2 | F6: 350 | G6: =E6*F6 -> 5670 | H6: 0 | I6: =G6-(G6*H6/100) -> 5670 | J6: Cheque | K6: Unpaid
A7: 46212 | B7: INV-1006 | C7: Sharma Dairy Shop | D7: Raw Milk | E7: 19 | F7: 60 | G7: =E7*F7 -> 1140 | H7: 2.5 | I7: =G7-(G7*H7/100) -> 1111.5 | J7: Cash | K7: Partial
A8: 46211 | B8: INV-1007 | C8: Bhatbhateni Supermarket | D8: Cow Milk | E8: 21.8 | F8: 65 | G8: =E8*F8 -> 1417 | H8: 2.5 | I8: =G8-(G8*H8/100) -> 1381.575 | J8: Credit | K8: Paid
A9: 46210 | B9: INV-1008 | C9: Patan Co-op | D9: Curd (Dahi) | E9: 24.6 | F9: 100 | G9: =E9*F9 -> 2460 | H9: 2.5 | I9: =G9-(G9*H9/100) -> 2398.5 | J9: Bank Transfer | K9: Unpaid
A10: 46209 | B10: INV-1009 | C10: Hotel Annapurna | D10: Ghee | E10: 27.4 | F10: 650 | G10: =E10*F10 -> 17810 | H10: 0 | I10: =G10-(G10*H10/100) -> 17810 | J10: UPI | K10: Partial
A11: 46208 | B11: INV-1010 | C11: Khadgi Sweets | D11: Paneer | E11: 30.2 | F11: 350 | G11: =E11*F11 -> 10570 | H11: 2.5 | I11: =G11-(G11*H11/100) -> 10305.75 | J11: Cheque | K11: Paid

Sheet Purchase_Entry
A1: Date | B1: Bill No | C1: Supplier Name | D1: Product | E1: FAT % | F1: SNF % | G1: Extra Per Unit | H1: Rate Type | I1: Fixed Rate Per Unit | J1: Rate Per Unit | K1: Quantity | L1: Amount | M1: Transport | N1: Net Amount | O1: Payment Mode | P1: Status | Q1: Remarks
A2: 46217 | B2: BILL-5001 | C2: Gurung Dairy Farm | D2: Raw Milk | E2: 3.5 | F2: 8.5 | G2: 2 | H2: FORMULA | I2: 0 | J2: =IF(H2="FORMULA", IF(E2="",0,E2)*7.15 + IF(F2="",0,F2)*4.55 + IF(G2="",0,G2), IF(H2="FIXED", IF(I2="",0,I2), 0)) -> 65.7 | K2: 50 | L2: =IF(K2="",0,K2)*J2 -> 3285 | M2: 300 | N2: =L2+IF(M2="",0,M2) -> 3585 | O2: Cash | P2: Paid
A3: 46216 | B3: BILL-5002 | C3: Fresh Valley Suppliers | D3: Raw Milk | E3: 3.6 | F3: 8.55 | G3: 1 | H3: FORMULA | I3: 0 | J3: =IF(H3="FORMULA", IF(E3="",0,E3)*7.15 + IF(F3="",0,F3)*4.55 + IF(G3="",0,G3), IF(H3="FIXED", IF(I3="",0,I3), 0)) -> 65.6425 | K3: 62.5 | L3: =IF(K3="",0,K3)*J3 -> 4102.6563 | M3: 340 | N3: =L3+IF(M3="",0,M3) -> 4442.6563 | O3: Credit | P3: Unpaid
A4: 46215 | B4: BILL-5003 | C4: Patan Co-op | D4: Raw Milk | E4: 3.7 | F4: 8.6 | G4: 0 | H4: FORMULA | I4: 0 | J4: =IF(H4="FORMULA", IF(E4="",0,E4)*7.15 + IF(F4="",0,F4)*4.55 + IF(G4="",0,G4), IF(H4="FIXED", IF(I4="",0,I4), 0)) -> 65.585 | K4: 75 | L4: =IF(K4="",0,K4)*J4 -> 4918.875 | M4: 380 | N4: =L4+IF(M4="",0,M4) -> 5298.875 | O4: Bank Transfer | P4: Partial
A5: 46214 | B5: BILL-5004 | C5: Pokhara Ghee House | D5: Raw Milk | E5: 3.8 | F5: 8.65 | G5: 2 | H5: FORMULA | I5: 0 | J5: =IF(H5="FORMULA", IF(E5="",0,E5)*7.15 + IF(F5="",0,F5)*4.55 + IF(G5="",0,G5), IF(H5="FIXED", IF(I5="",0,I5), 0)) -> 68.5275 | K5: 87.5 | L5: =IF(K5="",0,K5)*J5 -> 5996.1562 | M5: 420 | N5: =L5+IF(M5="",0,M5) -> 6416.1562 | O5: Cheque | P5: Paid
A6: 46213 | B6: BILL-5005 | C6: Dairy Cooperative | D6: Ghee | E6: 0 | F6: 0 | G6: 1 | H6: FORMULA | I6: 0 | J6: =IF(H6="FORMULA", IF(E6="",0,E6)*7.15 + IF(F6="",0,F6)*4.55 + IF(G6="",0,G6), IF(H6="FIXED", IF(I6="",0,I6), 0)) -> 1 | K6: 100 | L6: =IF(K6="",0,K6)*J6 -> 100 | M6: 460 | N6: =L6+IF(M6="",0,M6) -> 560 | O6: UPI | P6: Unpaid
A7: 46212 | B7: BILL-5006 | C7: Gurung Dairy Farm | D7: Raw Milk | E7: 4 | F7: 8.75 | G7: 0 | H7: FORMULA | I7: 0 | J7: =IF(H7="FORMULA", IF(E7="",0,E7)*7.15 + IF(F7="",0,F7)*4.55 + IF(G7="",0,G7), IF(H7="FIXED", IF(I7="",0,I7), 0)) -> 68.4125 | K7: 112.5 | L7: =IF(K7="",0,K7)*J7 -> 7696.4062 | M7: 500 | N7: =L7+IF(M7="",0,M7) -> 8196.4062 | O7: Cash | P7: Partial
A8: 46211 | B8: BILL-5007 | C8: Fresh Valley Suppliers | D8: Cow Milk | E8: 4.1 | F8: 8.8 | G8: 2 | H8: FIXED | I8: 62 | J8: =IF(H8="FORMULA", IF(E8="",0,E8)*7.15 + IF(F8="",0,F8)*4.55 + IF(G8="",0,G8), IF(H8="FIXED", IF(I8="",0,I8), 0)) -> 62 | K8: 125 | L8: =IF(K8="",0,K8)*J8 -> 7750 | M8: 540 | N8: =L8+IF(M8="",0,M8) -> 8290 | O8: Credit | P8: Paid
A9: 46210 | B9: BILL-5008 | C9: Patan Co-op | D9: Buffalo Milk | E9: 4.2 | F9: 8.85 | G9: 1 | H9: FIXED | I9: 64 | J9: =IF(H9="FORMULA", IF(E9="",0,E9)*7.15 + IF(F9="",0,F9)*4.55 + IF(G9="",0,G9), IF(H9="FIXED", IF(I9="",0,I9), 0)) -> 64 | K9: 137.5 | L9: =IF(K9="",0,K9)*J9 -> 8800 | M9: 580 | N9: =L9+IF(M9="",0,M9) -> 9380 | O9: Bank Transfer | P9: Unpaid
A12: 📌 MILK PURCHASE PRICING RULES
A13: Rate Per Unit = (FAT % × 7.15) + (SNF % × 4.55) + Extra Per Unit when Rate Type = "FORMULA"
A14: Rate Per Unit = Fixed Rate Per Unit when Rate Type = "FIXED"
A15: Amount = Quantity × Rate Per Unit
A16: Net Amount = Amount + Transport Charges
A17: FAT Rate Multiplier: 7.15 per unit | SNF Rate Multiplier: 4.55 per unit
A18: Extra Per Unit is any additional contract amount (e.g., +2 per liter)
A19: 💡 Select Rate Type = FIXED for simple flat-rate purchases (e.g., Rs. 50/liter)

Sheet Cash_Collection
A1: Date | B1: Receipt No | C1: Customer Name | D1: Against Bill No | E1: Opening Due | F1: Collected Amount | G1: Payment Mode | H1: Closing Due | I1: Remarks
A2: 46207 | B2: R001 | C2: Sharma Dairy Shop | D2: INV-1001 | E2: 5800 | F2: 5800 | G2: Cash | H2: =E2-F2 -> 0 | I2: Full payment received
A3: 46209 | B3: R002 | C3: Krishna Store | D3: INV-1004 | E3: 3960 | F3: 3960 | G3: Cash | H3: =E3-F3 -> 0 | I3: Full payment
A4: 46211 | B4: R003 | C4: Patan Co-op | D4: INV-1005 | E4: 7200 | F4: 5000 | G4: Bank Transfer | H4: =E4-F4 -> 2200 | I4: Partial payment
A5: 46212 | B5: R004 | C5: Bhatbhateni Supermarket | D5: INV-1002 | E5: 8500 | F5: 8500 | G5: Cheque | H5: =E5-F5 -> 0 | I5: Full payment via cheque
A6: 46214 | B6: R005 | C6: Hotel Annapurna | D6: INV-1003 | E6: 3200 | F6: 3200 | G6: Cash | H6: =E6-F6 -> 0
A7: 46216 | B7: R006 | C7: Patan Co-op | D7: INV-1005 | E7: 2200 | F7: 2200 | G7: UPI | H7: =E7-F7 -> 0 | I7: Balance cleared

Sheet Stock_Master
A1: Product Name | B1: Unit | C1: Opening Stock | D1: Purchases In | E1: Sales Out | F1: Current Stock | G1: Reorder Level | H1: Rate (Rs) | I1: Stock Value | J1: Status
A2: Raw Milk | B2: Liter | C2: 1000 | D2: =SUMIF(Purchase_Entry!D$2:D$5000,A2,Purchase_Entry!K$2:K$5000) -> 387.5 | E2: =SUMIF(Sales_Entry!D$2:D$5000,A2,Sales_Entry!E$2:E$5000) -> 24 | F2: =C2+D2-E2 -> 1363.5 | G2: 200 | H2: 60 | I2: =F2*H2 -> 81810 | J2: =IF(F2<=G2,"Reorder",IF(F2<=(G2*1.5),"Low Stock","In Stock")) -> In Stock
A3: Cow Milk | B3: Liter | C3: 500 | D3: =SUMIF(Purchase_Entry!D$2:D$5000,A3,Purchase_Entry!K$2:K$5000) -> 125 | E3: =SUMIF(Sales_Entry!D$2:D$5000,A3,Sales_Entry!E$2:E$5000) -> 29.6 | F3: =C3+D3-E3 -> 595.4 | G3: 100 | H3: 65 | I3: =F3*H3 -> 38701 | J3: =IF(F3<=G3,"Reorder",IF(F3<=(G3*1.5),"Low Stock","In Stock")) -> In Stock
A4: Curd (Dahi) | B4: Kg | C4: 100 | D4: =SUMIF(Purchase_Entry!D$2:D$5000,A4,Purchase_Entry!K$2:K$5000) -> 0 | E4: =SUMIF(Sales_Entry!D$2:D$5000,A4,Sales_Entry!E$2:E$5000) -> 35.2 | F4: =C4+D4-E4 -> 64.8 | G4: 20 | H4: 100 | I4: =F4*H4 -> 6480 | J4: =IF(F4<=G4,"Reorder",IF(F4<=(G4*1.5),"Low Stock","In Stock")) -> In Stock
A5: Ghee | B5: Kg | C5: 50 | D5: =SUMIF(Purchase_Entry!D$2:D$5000,A5,Purchase_Entry!K$2:K$5000) -> 100 | E5: =SUMIF(Sales_Entry!D$2:D$5000,A5,Sales_Entry!E$2:E$5000) -> 40.8 | F5: =C5+D5-E5 -> 109.2 | G5: 10 | H5: 650 | I5: =F5*H5 -> 70980 | J5: =IF(F5<=G5,"Reorder",IF(F5<=(G5*1.5),"Low Stock","In Stock")) -> In Stock
A6: Paneer | B6: Kg | C6: 30 | D6: =SUMIF(Purchase_Entry!D$2:D$5000,A6,Purchase_Entry!K$2:K$5000) -> 0 | E6: =SUMIF(Sales_Entry!D$2:D$5000,A6,Sales_Entry!E$2:E$5000) -> 46.4 | F6: =C6+D6-E6 -> -16.4 | G6: 5 | H6: 350 | I6: =F6*H6 -> -5740 | J6: =IF(F6<=G6,"Reorder",IF(F6<=(G6*1.5),"Low Stock","In Stock")) -> Reorder
A7: Butter | B7: Kg | C7: 20 | D7: =SUMIF(Purchase_Entry!D$2:D$5000,A7,Purchase_Entry!K$2:K$5000) -> 0 | E7: =SUMIF(Sales_Entry!D$2:D$5000,A7,Sales_Entry!E$2:E$5000) -> 0 | F7: =C7+D7-E7 -> 20 | G7: 5 | H7: 450 | I7: =F7*H7 -> 9000 | J7: =IF(F7<=G7,"Reorder",IF(F7<=(G7*1.5),"Low Stock","In Stock")) -> In Stock
A8: Buttermilk | B8: Liter | C8: 60 | D8: =SUMIF(Purchase_Entry!D$2:D$5000,A8,Purchase_Entry!K$2:K$5000) -> 0 | E8: =SUMIF(Sales_Entry!D$2:D$5000,A8,Sales_Entry!E$2:E$5000) -> 0 | F8: =C8+D8-E8 -> 60 | G8: 15 | H8: 40 | I8: =F8*H8 -> 2400 | J8: =IF(F8<=G8,"Reorder",IF(F8<=(G8*1.5),"Low Stock","In Stock")) -> In Stock
A9: Khoya | B9: Kg | C9: 15 | D9: =SUMIF(Purchase_Entry!D$2:D$5000,A9,Purchase_Entry!K$2:K$5000) -> 0 | E9: =SUMIF(Sales_Entry!D$2:D$5000,A9,Sales_Entry!E$2:E$5000) -> 0 | F9: =C9+D9-E9 -> 15 | G9: 5 | H9: 300 | I9: =F9*H9 -> 4500 | J9: =IF(F9<=G9,"Reorder",IF(F9<=(G9*1.5),"Low Stock","In Stock")) -> In Stock

Sheet Party_Master
A1: Party Name | B1: Type | C1: Phone | D1: Address | E1: Opening Balance | F1: Total Debit | G1: Total Credit | H1: Running Balance | I1: Status
A2: Sharma Dairy Shop | B2: Customer | C2: 9812345670 | D2: New Road, Kathmandu | E2: 15000 | F2: =SUMIF(Party_Ledger!B$2:B$5000,A2,Party_Ledger!F$2:F$5000) -> 24050 | G2: =SUMIF(Party_Ledger!B$2:B$5000,A2,Party_Ledger!G$2:G$5000) -> 10000 | H2: =E2+F2-G2 -> 29050 | I2: =IF(H2>0,"Outstanding",IF(H2<0,"Payable","Settled")) -> Outstanding
A3: Bhatbhateni Supermarket | B3: Customer | C3: 9812345672 | D3: Durbar Marg, Kathmandu | E3: 45000 | F3: =SUMIF(Party_Ledger!B$2:B$5000,A3,Party_Ledger!F$2:F$5000) -> 0 | G3: =SUMIF(Party_Ledger!B$2:B$5000,A3,Party_Ledger!G$2:G$5000) -> 0 | H3: =E3+F3-G3 -> 45000 | I3: =IF(H3>0,"Outstanding",IF(H3<0,"Payable","Settled")) -> Outstanding
A4: Gurung Dairy Farm | B4: Supplier | C4: 9852345673 | D4: Budhanilkantha | E4: 50000 | F4: =SUMIF(Party_Ledger!B$2:B$5000,A4,Party_Ledger!F$2:F$5000) -> 30000 | G4: =SUMIF(Party_Ledger!B$2:B$5000,A4,Party_Ledger!G$2:G$5000) -> 73700 | H4: =E4+F4-G4 -> 6300 | I4: =IF(H4>0,"Outstanding",IF(H4<0,"Payable","Settled")) -> Outstanding
A5: Fresh Valley Suppliers | B5: Supplier | C5: 9841234570 | D5: Bhaktapur | E5: 12000 | F5: =SUMIF(Party_Ledger!B$2:B$5000,A5,Party_Ledger!F$2:F$5000) -> 0 | G5: =SUMIF(Party_Ledger!B$2:B$5000,A5,Party_Ledger!G$2:G$5000) -> 0 | H5: =E5+F5-G5 -> 12000 | I5: =IF(H5>0,"Outstanding",IF(H5<0,"Payable","Settled")) -> Outstanding
A6: Patan Co-op | B6: Both | C6: 9852345675 | D6: Patan, Lalitpur | E6: 0 | F6: =SUMIF(Party_Ledger!B$2:B$5000,A6,Party_Ledger!F$2:F$5000) -> 0 | G6: =SUMIF(Party_Ledger!B$2:B$5000,A6,Party_Ledger!G$2:G$5000) -> 0 | H6: =E6+F6-G6 -> 0 | I6: =IF(H6>0,"Outstanding",IF(H6<0,"Payable","Settled")) -> Settled
A7: Hotel Annapurna | B7: Customer | C7: 9811112233 | D7: Thamel, Kathmandu | E7: 0 | F7: =SUMIF(Party_Ledger!B$2:B$5000,A7,Party_Ledger!F$2:F$5000) -> 0 | G7: =SUMIF(Party_Ledger!B$2:B$5000,A7,Party_Ledger!G$2:G$5000) -> 0 | H7: =E7+F7-G7 -> 0 | I7: =IF(H7>0,"Outstanding",IF(H7<0,"Payable","Settled")) -> Settled
A8: Khadgi Sweets | B8: Customer | C8: 9843322110 | D8: Asan, Kathmandu | E8: 8000 | F8: =SUMIF(Party_Ledger!B$2:B$5000,A8,Party_Ledger!F$2:F$5000) -> 0 | G8: =SUMIF(Party_Ledger!B$2:B$5000,A8,Party_Ledger!G$2:G$5000) -> 0 | H8: =E8+F8-G8 -> 8000 | I8: =IF(H8>0,"Outstanding",IF(H8<0,"Payable","Settled")) -> Outstanding
A9: Pokhara Ghee House | B9: Supplier | C9: 9856001122 | D9: Pokhara | E9: 25000 | F9: =SUMIF(Party_Ledger!B$2:B$5000,A9,Party_Ledger!F$2:F$5000) -> 0 | G9: =SUMIF(Party_Ledger!B$2:B$5000,A9,Party_Ledger!G$2:G$5000) -> 0 | H9: =E9+F9-G9 -> 25000 | I9: =IF(H9>0,"Outstanding",IF(H9<0,"Payable","Settled")) -> Outstanding
A10: Dairy Cooperative | B10: Both | C10: 9812345699 | D10: Chitwan | E10: 0 | F10: =SUMIF(Party_Ledger!B$2:B$5000,A10,Party_Ledger!F$2:F$5000) -> 0 | G10: =SUMIF(Party_Ledger!B$2:B$5000,A10,Party_Ledger!G$2:G$5000) -> 0 | H10: =E10+F10-G10 -> 0 | I10: =IF(H10>0,"Outstanding",IF(H10<0,"Payable","Settled")) -> Settled

Sheet Party_Ledger
A1: Date | B1: Party Name | C1: Transaction Type | D1: Reference No | E1: Description | F1: Debit | G1: Credit | H1: Balance | I1: Remarks
A2: 46023 | B2: Sharma Dairy Shop | C2: Opening | E2: Opening Balance | F2: 15000 | G2: 0 | H2: 15000
A3: 46210 | B3: Sharma Dairy Shop | C3: Sale | D3: INV-1001 | E3: Sale of Milk & Products | F3: 5800 | G3: 0 | H3: =H2+F3-G3 -> 20800
A4: 46212 | B4: Sharma Dairy Shop | C4: Receipt | D4: PAY-101 | E4: Payment Received | F4: 0 | G4: 10000 | H4: =H3+F4-G4 -> 10800 | I4: Bank Transfer
A5: 46214 | B5: Sharma Dairy Shop | C5: Sale | D5: INV-1002 | E5: Ghee Sale | F5: 3250 | G5: 0 | H5: =H4+F5-G5 -> 14050
A6: 46023 | B6: Gurung Dairy Farm | C6: Opening | E6: Opening Balance | F6: 0 | G6: 50000 | H6: =H5+F6-G6 -> -35950
A7: 46211 | B7: Gurung Dairy Farm | C7: Purchase | D7: BILL-5001 | E7: Milk Purchase | F7: 0 | G7: 15300 | H7: =H6+F7-G7 -> -51250 | I7: Transport included
A8: 46213 | B8: Gurung Dairy Farm | C8: Payment | D8: PAY-102 | E8: Payment Made | F8: 30000 | G8: 0 | H8: =H7+F8-G8 -> -21250 | I8: Bank Transfer
A9: 46215 | B9: Gurung Dairy Farm | C9: Purchase | D9: BILL-5002 | E9: Ghee Supply | F9: 0 | G9: 8400 | H9: =H8+F9-G9 -> -29650

Sheet Denomination_Count
A1: 🐄 [Your Dairy Plant Name]
A2: 💰 Daily Cash Denomination Count
A3: Date | B3: Count ₹5 | C3: Count ₹10 | D3: Count ₹20 | E3: Count ₹50 | F3: Count ₹100 | G3: Count ₹500 | H3: Count ₹1000 | I3: Other Amount | J3: Grand Total
A4: 46217 | B4: 10 | C4: 15 | D4: 8 | E4: 5 | F4: 12 | G4: 3 | H4: 2 | I4: 50 | J4: =B4*5 + C4*10 + D4*20 + E4*50 + F4*100 + G4*500 + H4*1000 + I4 -> 5360
A5: 46216 | B5: 15 | C5: 18 | D5: 10 | E5: 6 | F5: 14 | G5: 4 | H5: 3 | I5: 65 | J5: =B5*5 + C5*10 + D5*20 + E5*50 + F5*100 + G5*500 + H5*1000 + I5 -> 7220
A6: 46215 | B6: 20 | C6: 21 | D6: 12 | E6: 7 | F6: 16 | G6: 5 | H6: 4 | I6: 80 | J6: =B6*5 + C6*10 + D6*20 + E6*50 + F6*100 + G6*500 + H6*1000 + I6 -> 9080
A7: 46214 | B7: 25 | C7: 24 | D7: 14 | E7: 8 | F7: 18 | G7: 6 | H7: 5 | I7: 95 | J7: =B7*5 + C7*10 + D7*20 + E7*50 + F7*100 + G7*500 + H7*1000 + I7 -> 10940
A8: 46213 | B8: 30 | C8: 27 | D8: 16 | E8: 9 | F8: 20 | G8: 7 | H8: 6 | I8: 110 | J8: =B8*5 + C8*10 + D8*20 + E8*50 + F8*100 + G8*500 + H8*1000 + I8 -> 12800
A9: 46212 | B9: 35 | C9: 30 | D9: 18 | E9: 10 | F9: 22 | G9: 8 | H9: 7 | I9: 125 | J9: =B9*5 + C9*10 + D9*20 + E9*50 + F9*100 + G9*500 + H9*1000 + I9 -> 14660
A10: 46211 | B10: 40 | C10: 33 | D10: 20 | E10: 11 | F10: 24 | G10: 9 | H10: 8 | I10: 140 | J10: =B10*5 + C10*10 + D10*20 + E10*50 + F10*100 + G10*500 + H10*1000 + I10 -> 16520
A11: 46210 | B11: 45 | C11: 36 | D11: 22 | E11: 12 | F11: 26 | G11: 10 | H11: 9 | I11: 155 | J11: =B11*5 + C11*10 + D11*20 + E11*50 + F11*100 + G11*500 + H11*1000 + I11 -> 18380
A12: 46209 | B12: 50 | C12: 39 | D12: 24 | E12: 13 | F12: 28 | G12: 11 | H12: 10 | I12: 170 | J12: =B12*5 + C12*10 + D12*20 + E12*50 + F12*100 + G12*500 + H12*1000 + I12 -> 20240
A13: 46208 | B13: 55 | C13: 42 | D13: 26 | E13: 14 | F13: 30 | G13: 12 | H13: 11 | I13: 185 | J13: =B13*5 + C13*10 + D13*20 + E13*50 + F13*100 + G13*500 + H13*1000 + I13 -> 22100
A14: TOTALS | B14: =SUM(B4:B13) -> 325 | C14: =SUM(C4:C13) -> 285 | D14: =SUM(D4:D13) -> 170 | E14: =SUM(E4:E13) -> 95 | F14: =SUM(F4:F13) -> 210 | G14: =SUM(G4:G13) -> 75 | H14: =SUM(H4:H13) -> 65 | I14: =SUM(I4:I13) -> 1175 | J14: =SUM(J4:J13) -> 137300

Sheet Sales_Report
A1: 🐄 SALES REPORT
A3: Filters: | E3: Summary:
A4: From Date: | B4: =1-Jul-2026 -> #NAME? | E4: Total Invoices: | F4: =COUNTIFS(Sales_Entry!A$2:A$5000,">="&B4,Sales_Entry!A$2:A$5000,"<="&B5) -> 0
A5: To Date: | B5: =14-Jul-2026 -> #NAME? | E5: Total Amount: | F5: =SUMIFS(Sales_Entry!J$2:J$5000,Sales_Entry!A$2:A$5000,">="&B4,Sales_Entry!A$2:A$5000,"<="&B5) -> 0
A6: Party: | B6: All | E6: Outstanding: | F6: =SUMIFS(Sales_Entry!J$2:J$5000,Sales_Entry!A$2:A$5000,">="&B4,Sales_Entry!A$2:A$5000,"<="&B5,Sales_Entry!K$2:K$5000,"Unpaid")+SUMIFS(Sales_Entry!J$2:J$5000,Sales_Entry!A$2:A$5000,">="&B4,Sales_Entry!A$2:A$5000,"<="&B5,Sales_Entry!K$2:K$5000,"Partial") -> 0
A8: Date | B8: Invoice No | C8: Party Name | D8: Product | E8: Quantity | F8: Rate | G8: Amount | H8: Discount % | I8: Net Amount | J8: Payment Mode | K8: Status
A9: =IFERROR(INDEX(Sales_Entry!A$2:A$5000,2),"") -> 46216 | B9: =IFERROR(INDEX(Sales_Entry!B$2:B$5000,2),"") -> INV-1002 | C9: =IFERROR(INDEX(Sales_Entry!C$2:C$5000,2),"") -> Bhatbhateni Supermarket | D9: =IFERROR(INDEX(Sales_Entry!D$2:D$5000,2),"") -> Cow Milk | E9: =IFERROR(INDEX(Sales_Entry!E$2:E$5000,2),"") -> 7.8 | F9: =IFERROR(INDEX(Sales_Entry!F$2:F$5000,2),"") -> 65 | G9: =IFERROR(INDEX(Sales_Entry!G$2:G$5000,2),"") -> 507 | H9: =IFERROR(INDEX(Sales_Entry!H$2:H$5000,2),"") -> 2.5 | ... K9: =IFERROR(INDEX(Sales_Entry!K$2:K$5000,2),"") -> Unpaid
A10: =IFERROR(INDEX(Sales_Entry!A$2:A$5000,3),"") -> 46215 | B10: =IFERROR(INDEX(Sales_Entry!B$2:B$5000,3),"") -> INV-1003 | C10: =IFERROR(INDEX(Sales_Entry!C$2:C$5000,3),"") -> Patan Co-op | D10: =IFERROR(INDEX(Sales_Entry!D$2:D$5000,3),"") -> Curd (Dahi) | E10: =IFERROR(INDEX(Sales_Entry!E$2:E$5000,3),"") -> 10.6 | F10: =IFERROR(INDEX(Sales_Entry!F$2:F$5000,3),"") -> 100 | G10: =IFERROR(INDEX(Sales_Entry!G$2:G$5000,3),"") -> 1060 | H10: =IFERROR(INDEX(Sales_Entry!H$2:H$5000,3),"") -> 2.5 | ... K10: =IFERROR(INDEX(Sales_Entry!K$2:K$5000,3),"") -> Partial
A11: =IFERROR(INDEX(Sales_Entry!A$2:A$5000,4),"") -> 46214 | B11: =IFERROR(INDEX(Sales_Entry!B$2:B$5000,4),"") -> INV-1004 | C11: =IFERROR(INDEX(Sales_Entry!C$2:C$5000,4),"") -> Hotel Annapurna | D11: =IFERROR(INDEX(Sales_Entry!D$2:D$5000,4),"") -> Ghee | E11: =IFERROR(INDEX(Sales_Entry!E$2:E$5000,4),"") -> 13.4 | F11: =IFERROR(INDEX(Sales_Entry!F$2:F$5000,4),"") -> 650 | G11: =IFERROR(INDEX(Sales_Entry!G$2:G$5000,4),"") -> 8710 | H11: =IFERROR(INDEX(Sales_Entry!H$2:H$5000,4),"") -> 2.5 | ... K11: =IFERROR(INDEX(Sales_Entry!K$2:K$5000,4),"") -> Paid
A12: =IFERROR(INDEX(Sales_Entry!A$2:A$5000,5),"") -> 46213 | B12: =IFERROR(INDEX(Sales_Entry!B$2:B$5000,5),"") -> INV-1005 | C12: =IFERROR(INDEX(Sales_Entry!C$2:C$5000,5),"") -> Khadgi Sweets | D12: =IFERROR(INDEX(Sales_Entry!D$2:D$5000,5),"") -> Paneer | E12: =IFERROR(INDEX(Sales_Entry!E$2:E$5000,5),"") -> 16.2 | F12: =IFERROR(INDEX(Sales_Entry!F$2:F$5000,5),"") -> 350 | G12: =IFERROR(INDEX(Sales_Entry!G$2:G$5000,5),"") -> 5670 | H12: =IFERROR(INDEX(Sales_Entry!H$2:H$5000,5),"") -> 0 | ... K12: =IFERROR(INDEX(Sales_Entry!K$2:K$5000,5),"") -> Unpaid
A13: =IFERROR(INDEX(Sales_Entry!A$2:A$5000,6),"") -> 46212 | B13: =IFERROR(INDEX(Sales_Entry!B$2:B$5000,6),"") -> INV-1006 | C13: =IFERROR(INDEX(Sales_Entry!C$2:C$5000,6),"") -> Sharma Dairy Shop | D13: =IFERROR(INDEX(Sales_Entry!D$2:D$5000,6),"") -> Raw Milk | E13: =IFERROR(INDEX(Sales_Entry!E$2:E$5000,6),"") -> 19 | F13: =IFERROR(INDEX(Sales_Entry!F$2:F$5000,6),"") -> 60 | G13: =IFERROR(INDEX(Sales_Entry!G$2:G$5000,6),"") -> 1140 | H13: =IFERROR(INDEX(Sales_Entry!H$2:H$5000,6),"") -> 2.5 | ... K13: =IFERROR(INDEX(Sales_Entry!K$2:K$5000,6),"") -> Partial
A14: =IFERROR(INDEX(Sales_Entry!A$2:A$5000,7),"") -> 46211 | B14: =IFERROR(INDEX(Sales_Entry!B$2:B$5000,7),"") -> INV-1007 | C14: =IFERROR(INDEX(Sales_Entry!C$2:C$5000,7),"") -> Bhatbhateni Supermarket | D14: =IFERROR(INDEX(Sales_Entry!D$2:D$5000,7),"") -> Cow Milk | E14: =IFERROR(INDEX(Sales_Entry!E$2:E$5000,7),"") -> 21.8 | F14: =IFERROR(INDEX(Sales_Entry!F$2:F$5000,7),"") -> 65 | G14: =IFERROR(INDEX(Sales_Entry!G$2:G$5000,7),"") -> 1417 | H14: =IFERROR(INDEX(Sales_Entry!H$2:H$5000,7),"") -> 2.5 | ... K14: =IFERROR(INDEX(Sales_Entry!K$2:K$5000,7),"") -> Paid
A15: =IFERROR(INDEX(Sales_Entry!A$2:A$5000,8),"") -> 46210 | B15: =IFERROR(INDEX(Sales_Entry!B$2:B$5000,8),"") -> INV-1008 | C15: =IFERROR(INDEX(Sales_Entry!C$2:C$5000,8),"") -> Patan Co-op | D15: =IFERROR(INDEX(Sales_Entry!D$2:D$5000,8),"") -> Curd (Dahi) | E15: =IFERROR(INDEX(Sales_Entry!E$2:E$5000,8),"") -> 24.6 | F15: =IFERROR(INDEX(Sales_Entry!F$2:F$5000,8),"") -> 100 | G15: =IFERROR(INDEX(Sales_Entry!G$2:G$5000,8),"") -> 2460 | H15: =IFERROR(INDEX(Sales_Entry!H$2:H$5000,8),"") -> 2.5 | ... K15: =IFERROR(INDEX(Sales_Entry!K$2:K$5000,8),"") -> Unpaid
A16: =IFERROR(INDEX(Sales_Entry!A$2:A$5000,9),"") -> 46209 | B16: =IFERROR(INDEX(Sales_Entry!B$2:B$5000,9),"") -> INV-1009 | C16: =IFERROR(INDEX(Sales_Entry!C$2:C$5000,9),"") -> Hotel Annapurna | D16: =IFERROR(INDEX(Sales_Entry!D$2:D$5000,9),"") -> Ghee | E16: =IFERROR(INDEX(Sales_Entry!E$2:E$5000,9),"") -> 27.4 | F16: =IFERROR(INDEX(Sales_Entry!F$2:F$5000,9),"") -> 650 | G16: =IFERROR(INDEX(Sales_Entry!G$2:G$5000,9),"") -> 17810 | H16: =IFERROR(INDEX(Sales_Entry!H$2:H$5000,9),"") -> 0 | ... K16: =IFERROR(INDEX(Sales_Entry!K$2:K$5000,9),"") -> Partial
A17: =IFERROR(INDEX(Sales_Entry!A$2:A$5000,10),"") -> 46208 | B17: =IFERROR(INDEX(Sales_Entry!B$2:B$5000,10),"") -> INV-1010 | C17: =IFERROR(INDEX(Sales_Entry!C$2:C$5000,10),"") -> Khadgi Sweets | D17: =IFERROR(INDEX(Sales_Entry!D$2:D$5000,10),"") -> Paneer | E17: =IFERROR(INDEX(Sales_Entry!E$2:E$5000,10),"") -> 30.2 | F17: =IFERROR(INDEX(Sales_Entry!F$2:F$5000,10),"") -> 350 | G17: =IFERROR(INDEX(Sales_Entry!G$2:G$5000,10),"") -> 10570 | H17: =IFERROR(INDEX(Sales_Entry!H$2:H$5000,10),"") -> 2.5 | ... K17: =IFERROR(INDEX(Sales_Entry!K$2:K$5000,10),"") -> Paid
A18: =IFERROR(INDEX(Sales_Entry!A$2:A$5000,11),"") -> 0 | B18: =IFERROR(INDEX(Sales_Entry!B$2:B$5000,11),"") -> 0 | C18: =IFERROR(INDEX(Sales_Entry!C$2:C$5000,11),"") -> 0 | D18: =IFERROR(INDEX(Sales_Entry!D$2:D$5000,11),"") -> 0 | E18: =IFERROR(INDEX(Sales_Entry!E$2:E$5000,11),"") -> 0 | F18: =IFERROR(INDEX(Sales_Entry!F$2:F$5000,11),"") -> 0 | G18: =IFERROR(INDEX(Sales_Entry!G$2:G$5000,11),"") -> 0 | H18: =IFERROR(INDEX(Sales_Entry!H$2:H$5000,11),"") -> 0 | ... K18: =IFERROR(INDEX(Sales_Entry!K$2:K$5000,11),"") -> 0
A19: =IFERROR(INDEX(Sales_Entry!A$2:A$5000,12),"") -> 0 | B19: =IFERROR(INDEX(Sales_Entry!B$2:B$5000,12),"") -> 0 | C19: =IFERROR(INDEX(Sales_Entry!C$2:C$5000,12),"") -> 0 | D19: =IFERROR(INDEX(Sales_Entry!D$2:D$5000,12),"") -> 0 | E19: =IFERROR(INDEX(Sales_Entry!E$2:E$5000,12),"") -> 0 | F19: =IFERROR(INDEX(Sales_Entry!F$2:F$5000,12),"") -> 0 | G19: =IFERROR(INDEX(Sales_Entry!G$2:G$5000,12),"") -> 0 | H19: =IFERROR(INDEX(Sales_Entry!H$2:H$5000,12),"") -> 0 | ... K19: =IFERROR(INDEX(Sales_Entry!K$2:K$5000,12),"") -> 0
A20: =IFERROR(INDEX(Sales_Entry!A$2:A$5000,13),"") -> 0 | B20: =IFERROR(INDEX(Sales_Entry!B$2:B$5000,13),"") -> 0 | C20: =IFERROR(INDEX(Sales_Entry!C$2:C$5000,13),"") -> 0 | D20: =IFERROR(INDEX(Sales_Entry!D$2:D$5000,13),"") -> 0 | E20: =IFERROR(INDEX(Sales_Entry!E$2:E$5000,13),"") -> 0 | F20: =IFERROR(INDEX(Sales_Entry!F$2:F$5000,13),"") -> 0 | G20: =IFERROR(INDEX(Sales_Entry!G$2:G$5000,13),"") -> 0 | H20: =IFERROR(INDEX(Sales_Entry!H$2:H$5000,13),"") -> 0 | ... K20: =IFERROR(INDEX(Sales_Entry!K$2:K$5000,13),"") -> 0
A21: =IFERROR(INDEX(Sales_Entry!A$2:A$5000,14),"") -> 0 | B21: =IFERROR(INDEX(Sales_Entry!B$2:B$5000,14),"") -> 0 | C21: =IFERROR(INDEX(Sales_Entry!C$2:C$5000,14),"") -> 0 | D21: =IFERROR(INDEX(Sales_Entry!D$2:D$5000,14),"") -> 0 | E21: =IFERROR(INDEX(Sales_Entry!E$2:E$5000,14),"") -> 0 | F21: =IFERROR(INDEX(Sales_Entry!F$2:F$5000,14),"") -> 0 | G21: =IFERROR(INDEX(Sales_Entry!G$2:G$5000,14),"") -> 0 | H21: =IFERROR(INDEX(Sales_Entry!H$2:H$5000,14),"") -> 0 | ... K21: =IFERROR(INDEX(Sales_Entry!K$2:K$5000,14),"") -> 0
A22: =IFERROR(INDEX(Sales_Entry!A$2:A$5000,15),"") -> 0 | B22: =IFERROR(INDEX(Sales_Entry!B$2:B$5000,15),"") -> 0 | C22: =IFERROR(INDEX(Sales_Entry!C$2:C$5000,15),"") -> 0 | D22: =IFERROR(INDEX(Sales_Entry!D$2:D$5000,15),"") -> 0 | E22: =IFERROR(INDEX(Sales_Entry!E$2:E$5000,15),"") -> 0 | F22: =IFERROR(INDEX(Sales_Entry!F$2:F$5000,15),"") -> 0 | G22: =IFERROR(INDEX(Sales_Entry!G$2:G$5000,15),"") -> 0 | H22: =IFERROR(INDEX(Sales_Entry!H$2:H$5000,15),"") -> 0 | ... K22: =IFERROR(INDEX(Sales_Entry!K$2:K$5000,15),"") -> 0
A23: =IFERROR(INDEX(Sales_Entry!A$2:A$5000,16),"") -> 0 | B23: =IFERROR(INDEX(Sales_Entry!B$2:B$5000,16),"") -> 0 | C23: =IFERROR(INDEX(Sales_Entry!C$2:C$5000,16),"") -> 0 | D23: =IFERROR(INDEX(Sales_Entry!D$2:D$5000,16),"") -> 0 | E23: =IFERROR(INDEX(Sales_Entry!E$2:E$5000,16),"") -> 0 | F23: =IFERROR(INDEX(Sales_Entry!F$2:F$5000,16),"") -> 0 | G23: =IFERROR(INDEX(Sales_Entry!G$2:G$5000,16),"") -> 0 | H23: =IFERROR(INDEX(Sales_Entry!H$2:H$5000,16),"") -> 0 | ... K23: =IFERROR(INDEX(Sales_Entry!K$2:K$5000,16),"") -> 0
A24: =IFERROR(INDEX(Sales_Entry!A$2:A$5000,17),"") -> 0 | B24: =IFERROR(INDEX(Sales_Entry!B$2:B$5000,17),"") -> 0 | C24: =IFERROR(INDEX(Sales_Entry!C$2:C$5000,17),"") -> 0 | D24: =IFERROR(INDEX(Sales_Entry!D$2:D$5000,17),"") -> 0 | E24: =IFERROR(INDEX(Sales_Entry!E$2:E$5000,17),"") -> 0 | F24: =IFERROR(INDEX(Sales_Entry!F$2:F$5000,17),"") -> 0 | G24: =IFERROR(INDEX(Sales_Entry!G$2:G$5000,17),"") -> 0 | H24: =IFERROR(INDEX(Sales_Entry!H$2:H$5000,17),"") -> 0 | ... K24: =IFERROR(INDEX(Sales_Entry!K$2:K$5000,17),"") -> 0
A25: =IFERROR(INDEX(Sales_Entry!A$2:A$5000,18),"") -> 0 | B25: =IFERROR(INDEX(Sales_Entry!B$2:B$5000,18),"") -> 0 | C25: =IFERROR(INDEX(Sales_Entry!C$2:C$5000,18),"") -> 0 | D25: =IFERROR(INDEX(Sales_Entry!D$2:D$5000,18),"") -> 0 | E25: =IFERROR(INDEX(Sales_Entry!E$2:E$5000,18),"") -> 0 | F25: =IFERROR(INDEX(Sales_Entry!F$2:F$5000,18),"") -> 0 | G25: =IFERROR(INDEX(Sales_Entry!G$2:G$5000,18),"") -> 0 | H25: =IFERROR(INDEX(Sales_Entry!H$2:H$5000,18),"") -> 0 | ... K25: =IFERROR(INDEX(Sales_Entry!K$2:K$5000,18),"") -> 0
A26: =IFERROR(INDEX(Sales_Entry!A$2:A$5000,19),"") -> 0 | B26: =IFERROR(INDEX(Sales_Entry!B$2:B$5000,19),"") -> 0 | C26: =IFERROR(INDEX(Sales_Entry!C$2:C$5000,19),"") -> 0 | D26: =IFERROR(INDEX(Sales_Entry!D$2:D$5000,19),"") -> 0 | E26: =IFERROR(INDEX(Sales_Entry!E$2:E$5000,19),"") -> 0 | F26: =IFERROR(INDEX(Sales_Entry!F$2:F$5000,19),"") -> 0 | G26: =IFERROR(INDEX(Sales_Entry!G$2:G$5000,19),"") -> 0 | H26: =IFERROR(INDEX(Sales_Entry!H$2:H$5000,19),"") -> 0 | ... K26: =IFERROR(INDEX(Sales_Entry!K$2:K$5000,19),"") -> 0
A27: =IFERROR(INDEX(Sales_Entry!A$2:A$5000,20),"") -> 0 | B27: =IFERROR(INDEX(Sales_Entry!B$2:B$5000,20),"") -> 0 | C27: =IFERROR(INDEX(Sales_Entry!C$2:C$5000,20),"") -> 0 | D27: =IFERROR(INDEX(Sales_Entry!D$2:D$5000,20),"") -> 0 | E27: =IFERROR(INDEX(Sales_Entry!E$2:E$5000,20),"") -> 0 | F27: =IFERROR(INDEX(Sales_Entry!F$2:F$5000,20),"") -> 0 | G27: =IFERROR(INDEX(Sales_Entry!G$2:G$5000,20),"") -> 0 | H27: =IFERROR(INDEX(Sales_Entry!H$2:H$5000,20),"") -> 0 | ... K27: =IFERROR(INDEX(Sales_Entry!K$2:K$5000,20),"") -> 0
A28: =IFERROR(INDEX(Sales_Entry!A$2:A$5000,21),"") -> 0 | B28: =IFERROR(INDEX(Sales_Entry!B$2:B$5000,21),"") -> 0 | C28: =IFERROR(INDEX(Sales_Entry!C$2:C$5000,21),"") -> 0 | D28: =IFERROR(INDEX(Sales_Entry!D$2:D$5000,21),"") -> 0 | E28: =IFERROR(INDEX(Sales_Entry!E$2:E$5000,21),"") -> 0 | F28: =IFERROR(INDEX(Sales_Entry!F$2:F$5000,21),"") -> 0 | G28: =IFERROR(INDEX(Sales_Entry!G$2:G$5000,21),"") -> 0 | H28: =IFERROR(INDEX(Sales_Entry!H$2:H$5000,21),"") -> 0 | ... K28: =IFERROR(INDEX(Sales_Entry!K$2:K$5000,21),"") -> 0
A29: TOTALS | G29: =SUM(G9:G28) -> 49344 | I29: =SUM(I9:I28) -> 48697.4

Sheet Purchase_Report
A1: 🐄 PURCHASE REPORT
A3: Filters: | E3: Summary:
A4: From Date: | B4: =1-Jul-2026 -> #NAME? | E4: Total Bills: | F4: =COUNTIFS(Purchase_Entry!A$2:A$5000,">="&B4,Purchase_Entry!A$2:A$5000,"<="&B5) -> 0
A5: To Date: | B5: =14-Jul-2026 -> #NAME? | E5: Total Amount: | F5: =SUMIFS(Purchase_Entry!N$2:N$5000,Purchase_Entry!A$2:A$5000,">="&B4,Purchase_Entry!A$2:A$5000,"<="&B5) -> 0
A6: Supplier: | B6: All | E6: Payables: | F6: =SUMIFS(Purchase_Entry!N$2:N$5000,Purchase_Entry!A$2:A$5000,">="&B4,Purchase_Entry!A$2:A$5000,"<="&B5,Purchase_Entry!P$2:P$5000,"Unpaid")+SUMIFS(Purchase_Entry!N$2:N$5000,Purchase_Entry!A$2:A$5000,">="&B4,Purchase_Entry!A$2:A$5000,"<="&B5,Purchase_Entry!P$2:P$5000,"Partial") -> 0
A8: Date | B8: Bill No | C8: Supplier | D8: Product | E8: Quantity | F8: Rate | G8: Amount | H8: Transport | I8: Net Amount | J8: Payment Mode | K8: Status
A9: =IFERROR(INDEX(Purchase_Entry!A$2:A$5000,2),"") -> 46216 | B9: =IF(A9="","",INDEX(Purchase_Entry!B$2:B$5000,2)) -> BILL-5002 | C9: =IF(A9="","",INDEX(Purchase_Entry!C$2:C$5000,2)) -> Fresh Valley Suppliers | D9: =IF(A9="","",INDEX(Purchase_Entry!D$2:D$5000,2)) -> Raw Milk | E9: =IF(A9="","",INDEX(Purchase_Entry!K$2:K$5000,2)) -> 62.5 | F9: =IF(A9="","",INDEX(Purchase_Entry!J$2:J$5000,2)) -> 65.6425 | G9: =IF(A9="","",INDEX(Purchase_Entry!L$2:L$5000,2)) -> 4102.6563 | H9: =IF(A9="","",INDEX(Purchase_Entry!M$2:M$5000,2)) -> 340 | I9: =IF(A9="","",INDEX(Purchase_Entry!N$2:N$5000,2)) -> 4442.6563 | J9: =IF(A9="","",INDEX(Purchase_Entry!O$2:O$5000,2)) -> Credit | K9: =IF(A9="","",INDEX(Purchase_Entry!P$2:P$5000,2)) -> Unpaid
A10: =IFERROR(INDEX(Purchase_Entry!A$2:A$5000,3),"") -> 46215 | B10: =IF(A10="","",INDEX(Purchase_Entry!B$2:B$5000,3)) -> BILL-5003 | C10: =IF(A10="","",INDEX(Purchase_Entry!C$2:C$5000,3)) -> Patan Co-op | D10: =IF(A10="","",INDEX(Purchase_Entry!D$2:D$5000,3)) -> Raw Milk | E10: =IF(A10="","",INDEX(Purchase_Entry!K$2:K$5000,3)) -> 75 | F10: =IF(A10="","",INDEX(Purchase_Entry!J$2:J$5000,3)) -> 65.585 | G10: =IF(A10="","",INDEX(Purchase_Entry!L$2:L$5000,3)) -> 4918.875 | H10: =IF(A10="","",INDEX(Purchase_Entry!M$2:M$5000,3)) -> 380 | I10: =IF(A10="","",INDEX(Purchase_Entry!N$2:N$5000,3)) -> 5298.875 | J10: =IF(A10="","",INDEX(Purchase_Entry!O$2:O$5000,3)) -> Bank Transfer | K10: =IF(A10="","",INDEX(Purchase_Entry!P$2:P$5000,3)) -> Partial
A11: =IFERROR(INDEX(Purchase_Entry!A$2:A$5000,4),"") -> 46214 | B11: =IF(A11="","",INDEX(Purchase_Entry!B$2:B$5000,4)) -> BILL-5004 | C11: =IF(A11="","",INDEX(Purchase_Entry!C$2:C$5000,4)) -> Pokhara Ghee House | D11: =IF(A11="","",INDEX(Purchase_Entry!D$2:D$5000,4)) -> Raw Milk | E11: =IF(A11="","",INDEX(Purchase_Entry!K$2:K$5000,4)) -> 87.5 | F11: =IF(A11="","",INDEX(Purchase_Entry!J$2:J$5000,4)) -> 68.5275 | G11: =IF(A11="","",INDEX(Purchase_Entry!L$2:L$5000,4)) -> 5996.1562 | H11: =IF(A11="","",INDEX(Purchase_Entry!M$2:M$5000,4)) -> 420 | I11: =IF(A11="","",INDEX(Purchase_Entry!N$2:N$5000,4)) -> 6416.1562 | J11: =IF(A11="","",INDEX(Purchase_Entry!O$2:O$5000,4)) -> Cheque | K11: =IF(A11="","",INDEX(Purchase_Entry!P$2:P$5000,4)) -> Paid
A12: =IFERROR(INDEX(Purchase_Entry!A$2:A$5000,5),"") -> 46213 | B12: =IF(A12="","",INDEX(Purchase_Entry!B$2:B$5000,5)) -> BILL-5005 | C12: =IF(A12="","",INDEX(Purchase_Entry!C$2:C$5000,5)) -> Dairy Cooperative | D12: =IF(A12="","",INDEX(Purchase_Entry!D$2:D$5000,5)) -> Ghee | E12: =IF(A12="","",INDEX(Purchase_Entry!K$2:K$5000,5)) -> 100 | F12: =IF(A12="","",INDEX(Purchase_Entry!J$2:J$5000,5)) -> 1 | G12: =IF(A12="","",INDEX(Purchase_Entry!L$2:L$5000,5)) -> 100 | H12: =IF(A12="","",INDEX(Purchase_Entry!M$2:M$5000,5)) -> 460 | I12: =IF(A12="","",INDEX(Purchase_Entry!N$2:N$5000,5)) -> 560 | J12: =IF(A12="","",INDEX(Purchase_Entry!O$2:O$5000,5)) -> UPI | K12: =IF(A12="","",INDEX(Purchase_Entry!P$2:P$5000,5)) -> Unpaid
A13: =IFERROR(INDEX(Purchase_Entry!A$2:A$5000,6),"") -> 46212 | B13: =IF(A13="","",INDEX(Purchase_Entry!B$2:B$5000,6)) -> BILL-5006 | C13: =IF(A13="","",INDEX(Purchase_Entry!C$2:C$5000,6)) -> Gurung Dairy Farm | D13: =IF(A13="","",INDEX(Purchase_Entry!D$2:D$5000,6)) -> Raw Milk | E13: =IF(A13="","",INDEX(Purchase_Entry!K$2:K$5000,6)) -> 112.5 | F13: =IF(A13="","",INDEX(Purchase_Entry!J$2:J$5000,6)) -> 68.4125 | G13: =IF(A13="","",INDEX(Purchase_Entry!L$2:L$5000,6)) -> 7696.4062 | H13: =IF(A13="","",INDEX(Purchase_Entry!M$2:M$5000,6)) -> 500 | I13: =IF(A13="","",INDEX(Purchase_Entry!N$2:N$5000,6)) -> 8196.4062 | J13: =IF(A13="","",INDEX(Purchase_Entry!O$2:O$5000,6)) -> Cash | K13: =IF(A13="","",INDEX(Purchase_Entry!P$2:P$5000,6)) -> Partial
A14: =IFERROR(INDEX(Purchase_Entry!A$2:A$5000,7),"") -> 46211 | B14: =IF(A14="","",INDEX(Purchase_Entry!B$2:B$5000,7)) -> BILL-5007 | C14: =IF(A14="","",INDEX(Purchase_Entry!C$2:C$5000,7)) -> Fresh Valley Suppliers | D14: =IF(A14="","",INDEX(Purchase_Entry!D$2:D$5000,7)) -> Cow Milk | E14: =IF(A14="","",INDEX(Purchase_Entry!K$2:K$5000,7)) -> 125 | F14: =IF(A14="","",INDEX(Purchase_Entry!J$2:J$5000,7)) -> 62 | G14: =IF(A14="","",INDEX(Purchase_Entry!L$2:L$5000,7)) -> 7750 | H14: =IF(A14="","",INDEX(Purchase_Entry!M$2:M$5000,7)) -> 540 | I14: =IF(A14="","",INDEX(Purchase_Entry!N$2:N$5000,7)) -> 8290 | J14: =IF(A14="","",INDEX(Purchase_Entry!O$2:O$5000,7)) -> Credit | K14: =IF(A14="","",INDEX(Purchase_Entry!P$2:P$5000,7)) -> Paid
A15: =IFERROR(INDEX(Purchase_Entry!A$2:A$5000,8),"") -> 46210 | B15: =IF(A15="","",INDEX(Purchase_Entry!B$2:B$5000,8)) -> BILL-5008 | C15: =IF(A15="","",INDEX(Purchase_Entry!C$2:C$5000,8)) -> Patan Co-op | D15: =IF(A15="","",INDEX(Purchase_Entry!D$2:D$5000,8)) -> Buffalo Milk | E15: =IF(A15="","",INDEX(Purchase_Entry!K$2:K$5000,8)) -> 137.5 | F15: =IF(A15="","",INDEX(Purchase_Entry!J$2:J$5000,8)) -> 64 | G15: =IF(A15="","",INDEX(Purchase_Entry!L$2:L$5000,8)) -> 8800 | H15: =IF(A15="","",INDEX(Purchase_Entry!M$2:M$5000,8)) -> 580 | I15: =IF(A15="","",INDEX(Purchase_Entry!N$2:N$5000,8)) -> 9380 | J15: =IF(A15="","",INDEX(Purchase_Entry!O$2:O$5000,8)) -> Bank Transfer | K15: =IF(A15="","",INDEX(Purchase_Entry!P$2:P$5000,8)) -> Unpaid
A16: =IFERROR(INDEX(Purchase_Entry!A$2:A$5000,9),"") -> 0 | B16: =IF(A16="","",INDEX(Purchase_Entry!B$2:B$5000,9)) -> 0 | C16: =IF(A16="","",INDEX(Purchase_Entry!C$2:C$5000,9)) -> 0 | D16: =IF(A16="","",INDEX(Purchase_Entry!D$2:D$5000,9)) -> 0 | E16: =IF(A16="","",INDEX(Purchase_Entry!K$2:K$5000,9)) -> 0 | F16: =IF(A16="","",INDEX(Purchase_Entry!J$2:J$5000,9)) -> 0 | G16: =IF(A16="","",INDEX(Purchase_Entry!L$2:L$5000,9)) -> 0 | H16: =IF(A16="","",INDEX(Purchase_Entry!M$2:M$5000,9)) -> 0 | I16: =IF(A16="","",INDEX(Purchase_Entry!N$2:N$5000,9)) -> 0 | J16: =IF(A16="","",INDEX(Purchase_Entry!O$2:O$5000,9)) -> 0 | K16: =IF(A16="","",INDEX(Purchase_Entry!P$2:P$5000,9)) -> 0
A17: =IFERROR(INDEX(Purchase_Entry!A$2:A$5000,10),"") -> 0 | B17: =IF(A17="","",INDEX(Purchase_Entry!B$2:B$5000,10)) -> 0 | C17: =IF(A17="","",INDEX(Purchase_Entry!C$2:C$5000,10)) -> 0 | D17: =IF(A17="","",INDEX(Purchase_Entry!D$2:D$5000,10)) -> 0 | E17: =IF(A17="","",INDEX(Purchase_Entry!K$2:K$5000,10)) -> 0 | F17: =IF(A17="","",INDEX(Purchase_Entry!J$2:J$5000,10)) -> 0 | G17: =IF(A17="","",INDEX(Purchase_Entry!L$2:L$5000,10)) -> 0 | H17: =IF(A17="","",INDEX(Purchase_Entry!M$2:M$5000,10)) -> 0 | I17: =IF(A17="","",INDEX(Purchase_Entry!N$2:N$5000,10)) -> 0 | J17: =IF(A17="","",INDEX(Purchase_Entry!O$2:O$5000,10)) -> 0 | K17: =IF(A17="","",INDEX(Purchase_Entry!P$2:P$5000,10)) -> 0
A18: =IFERROR(INDEX(Purchase_Entry!A$2:A$5000,11),"") -> 📌 MILK PURCHASE PRICING RULES | B18: =IF(A18="","",INDEX(Purchase_Entry!B$2:B$5000,11)) -> 0 | C18: =IF(A18="","",INDEX(Purchase_Entry!C$2:C$5000,11)) -> 0 | D18: =IF(A18="","",INDEX(Purchase_Entry!D$2:D$5000,11)) -> 0 | E18: =IF(A18="","",INDEX(Purchase_Entry!K$2:K$5000,11)) -> 0 | F18: =IF(A18="","",INDEX(Purchase_Entry!J$2:J$5000,11)) -> 0 | G18: =IF(A18="","",INDEX(Purchase_Entry!L$2:L$5000,11)) -> 0 | H18: =IF(A18="","",INDEX(Purchase_Entry!M$2:M$5000,11)) -> 0 | I18: =IF(A18="","",INDEX(Purchase_Entry!N$2:N$5000,11)) -> 0 | J18: =IF(A18="","",INDEX(Purchase_Entry!O$2:O$5000,11)) -> 0 | K18: =IF(A18="","",INDEX(Purchase_Entry!P$2:P$5000,11)) -> 0
A19: =IFERROR(INDEX(Purchase_Entry!A$2:A$5000,12),"") -> Rate Per Unit = (FAT % × 7.15) + (SNF % × 4.55) + Extra Per Unit when Rate Type = "FORMULA" | B19: =IF(A19="","",INDEX(Purchase_Entry!B$2:B$5000,12)) -> 0 | C19: =IF(A19="","",INDEX(Purchase_Entry!C$2:C$5000,12)) -> 0 | D19: =IF(A19="","",INDEX(Purchase_Entry!D$2:D$5000,12)) -> 0 | E19: =IF(A19="","",INDEX(Purchase_Entry!K$2:K$5000,12)) -> 0 | F19: =IF(A19="","",INDEX(Purchase_Entry!J$2:J$5000,12)) -> 0 | G19: =IF(A19="","",INDEX(Purchase_Entry!L$2:L$5000,12)) -> 0 | H19: =IF(A19="","",INDEX(Purchase_Entry!M$2:M$5000,12)) -> 0 | I19: =IF(A19="","",INDEX(Purchase_Entry!N$2:N$5000,12)) -> 0 | J19: =IF(A19="","",INDEX(Purchase_Entry!O$2:O$5000,12)) -> 0 | K19: =IF(A19="","",INDEX(Purchase_Entry!P$2:P$5000,12)) -> 0
A20: =IFERROR(INDEX(Purchase_Entry!A$2:A$5000,13),"") -> Rate Per Unit = Fixed Rate Per Unit when Rate Type = "FIXED" | B20: =IF(A20="","",INDEX(Purchase_Entry!B$2:B$5000,13)) -> 0 | C20: =IF(A20="","",INDEX(Purchase_Entry!C$2:C$5000,13)) -> 0 | D20: =IF(A20="","",INDEX(Purchase_Entry!D$2:D$5000,13)) -> 0 | E20: =IF(A20="","",INDEX(Purchase_Entry!K$2:K$5000,13)) -> 0 | F20: =IF(A20="","",INDEX(Purchase_Entry!J$2:J$5000,13)) -> 0 | G20: =IF(A20="","",INDEX(Purchase_Entry!L$2:L$5000,13)) -> 0 | H20: =IF(A20="","",INDEX(Purchase_Entry!M$2:M$5000,13)) -> 0 | I20: =IF(A20="","",INDEX(Purchase_Entry!N$2:N$5000,13)) -> 0 | J20: =IF(A20="","",INDEX(Purchase_Entry!O$2:O$5000,13)) -> 0 | K20: =IF(A20="","",INDEX(Purchase_Entry!P$2:P$5000,13)) -> 0
A21: =IFERROR(INDEX(Purchase_Entry!A$2:A$5000,14),"") -> Amount = Quantity × Rate Per Unit | B21: =IF(A21="","",INDEX(Purchase_Entry!B$2:B$5000,14)) -> 0 | C21: =IF(A21="","",INDEX(Purchase_Entry!C$2:C$5000,14)) -> 0 | D21: =IF(A21="","",INDEX(Purchase_Entry!D$2:D$5000,14)) -> 0 | E21: =IF(A21="","",INDEX(Purchase_Entry!K$2:K$5000,14)) -> 0 | F21: =IF(A21="","",INDEX(Purchase_Entry!J$2:J$5000,14)) -> 0 | G21: =IF(A21="","",INDEX(Purchase_Entry!L$2:L$5000,14)) -> 0 | H21: =IF(A21="","",INDEX(Purchase_Entry!M$2:M$5000,14)) -> 0 | I21: =IF(A21="","",INDEX(Purchase_Entry!N$2:N$5000,14)) -> 0 | J21: =IF(A21="","",INDEX(Purchase_Entry!O$2:O$5000,14)) -> 0 | K21: =IF(A21="","",INDEX(Purchase_Entry!P$2:P$5000,14)) -> 0
A22: =IFERROR(INDEX(Purchase_Entry!A$2:A$5000,15),"") -> Net Amount = Amount + Transport Charges | B22: =IF(A22="","",INDEX(Purchase_Entry!B$2:B$5000,15)) -> 0 | C22: =IF(A22="","",INDEX(Purchase_Entry!C$2:C$5000,15)) -> 0 | D22: =IF(A22="","",INDEX(Purchase_Entry!D$2:D$5000,15)) -> 0 | E22: =IF(A22="","",INDEX(Purchase_Entry!K$2:K$5000,15)) -> 0 | F22: =IF(A22="","",INDEX(Purchase_Entry!J$2:J$5000,15)) -> 0 | G22: =IF(A22="","",INDEX(Purchase_Entry!L$2:L$5000,15)) -> 0 | H22: =IF(A22="","",INDEX(Purchase_Entry!M$2:M$5000,15)) -> 0 | I22: =IF(A22="","",INDEX(Purchase_Entry!N$2:N$5000,15)) -> 0 | J22: =IF(A22="","",INDEX(Purchase_Entry!O$2:O$5000,15)) -> 0 | K22: =IF(A22="","",INDEX(Purchase_Entry!P$2:P$5000,15)) -> 0
A23: =IFERROR(INDEX(Purchase_Entry!A$2:A$5000,16),"") -> FAT Rate Multiplier: 7.15 per unit | SNF Rate Multiplier: 4.55 per unit | B23: =IF(A23="","",INDEX(Purchase_Entry!B$2:B$5000,16)) -> 0 | C23: =IF(A23="","",INDEX(Purchase_Entry!C$2:C$5000,16)) -> 0 | D23: =IF(A23="","",INDEX(Purchase_Entry!D$2:D$5000,16)) -> 0 | E23: =IF(A23="","",INDEX(Purchase_Entry!K$2:K$5000,16)) -> 0 | F23: =IF(A23="","",INDEX(Purchase_Entry!J$2:J$5000,16)) -> 0 | G23: =IF(A23="","",INDEX(Purchase_Entry!L$2:L$5000,16)) -> 0 | H23: =IF(A23="","",INDEX(Purchase_Entry!M$2:M$5000,16)) -> 0 | I23: =IF(A23="","",INDEX(Purchase_Entry!N$2:N$5000,16)) -> 0 | J23: =IF(A23="","",INDEX(Purchase_Entry!O$2:O$5000,16)) -> 0 | K23: =IF(A23="","",INDEX(Purchase_Entry!P$2:P$5000,16)) -> 0
A24: =IFERROR(INDEX(Purchase_Entry!A$2:A$5000,17),"") -> Extra Per Unit is any additional contract amount (e.g., +2 per liter) | B24: =IF(A24="","",INDEX(Purchase_Entry!B$2:B$5000,17)) -> 0 | C24: =IF(A24="","",INDEX(Purchase_Entry!C$2:C$5000,17)) -> 0 | D24: =IF(A24="","",INDEX(Purchase_Entry!D$2:D$5000,17)) -> 0 | E24: =IF(A24="","",INDEX(Purchase_Entry!K$2:K$5000,17)) -> 0 | F24: =IF(A24="","",INDEX(Purchase_Entry!J$2:J$5000,17)) -> 0 | G24: =IF(A24="","",INDEX(Purchase_Entry!L$2:L$5000,17)) -> 0 | H24: =IF(A24="","",INDEX(Purchase_Entry!M$2:M$5000,17)) -> 0 | I24: =IF(A24="","",INDEX(Purchase_Entry!N$2:N$5000,17)) -> 0 | J24: =IF(A24="","",INDEX(Purchase_Entry!O$2:O$5000,17)) -> 0 | K24: =IF(A24="","",INDEX(Purchase_Entry!P$2:P$5000,17)) -> 0
A25: =IFERROR(INDEX(Purchase_Entry!A$2:A$5000,18),"") -> 💡 Select Rate Type = FIXED for simple flat-rate purchases (e.g., Rs. 50/liter) | B25: =IF(A25="","",INDEX(Purchase_Entry!B$2:B$5000,18)) -> 0 | C25: =IF(A25="","",INDEX(Purchase_Entry!C$2:C$5000,18)) -> 0 | D25: =IF(A25="","",INDEX(Purchase_Entry!D$2:D$5000,18)) -> 0 | E25: =IF(A25="","",INDEX(Purchase_Entry!K$2:K$5000,18)) -> 0 | F25: =IF(A25="","",INDEX(Purchase_Entry!J$2:J$5000,18)) -> 0 | G25: =IF(A25="","",INDEX(Purchase_Entry!L$2:L$5000,18)) -> 0 | H25: =IF(A25="","",INDEX(Purchase_Entry!M$2:M$5000,18)) -> 0 | I25: =IF(A25="","",INDEX(Purchase_Entry!N$2:N$5000,18)) -> 0 | J25: =IF(A25="","",INDEX(Purchase_Entry!O$2:O$5000,18)) -> 0 | K25: =IF(A25="","",INDEX(Purchase_Entry!P$2:P$5000,18)) -> 0
A26: =IFERROR(INDEX(Purchase_Entry!A$2:A$5000,19),"") -> 0 | B26: =IF(A26="","",INDEX(Purchase_Entry!B$2:B$5000,19)) -> 0 | C26: =IF(A26="","",INDEX(Purchase_Entry!C$2:C$5000,19)) -> 0 | D26: =IF(A26="","",INDEX(Purchase_Entry!D$2:D$5000,19)) -> 0 | E26: =IF(A26="","",INDEX(Purchase_Entry!K$2:K$5000,19)) -> 0 | F26: =IF(A26="","",INDEX(Purchase_Entry!J$2:J$5000,19)) -> 0 | G26: =IF(A26="","",INDEX(Purchase_Entry!L$2:L$5000,19)) -> 0 | H26: =IF(A26="","",INDEX(Purchase_Entry!M$2:M$5000,19)) -> 0 | I26: =IF(A26="","",INDEX(Purchase_Entry!N$2:N$5000,19)) -> 0 | J26: =IF(A26="","",INDEX(Purchase_Entry!O$2:O$5000,19)) -> 0 | K26: =IF(A26="","",INDEX(Purchase_Entry!P$2:P$5000,19)) -> 0
A27: =IFERROR(INDEX(Purchase_Entry!A$2:A$5000,20),"") -> 0 | B27: =IF(A27="","",INDEX(Purchase_Entry!B$2:B$5000,20)) -> 0 | C27: =IF(A27="","",INDEX(Purchase_Entry!C$2:C$5000,20)) -> 0 | D27: =IF(A27="","",INDEX(Purchase_Entry!D$2:D$5000,20)) -> 0 | E27: =IF(A27="","",INDEX(Purchase_Entry!K$2:K$5000,20)) -> 0 | F27: =IF(A27="","",INDEX(Purchase_Entry!J$2:J$5000,20)) -> 0 | G27: =IF(A27="","",INDEX(Purchase_Entry!L$2:L$5000,20)) -> 0 | H27: =IF(A27="","",INDEX(Purchase_Entry!M$2:M$5000,20)) -> 0 | I27: =IF(A27="","",INDEX(Purchase_Entry!N$2:N$5000,20)) -> 0 | J27: =IF(A27="","",INDEX(Purchase_Entry!O$2:O$5000,20)) -> 0 | K27: =IF(A27="","",INDEX(Purchase_Entry!P$2:P$5000,20)) -> 0
A28: =IFERROR(INDEX(Purchase_Entry!A$2:A$5000,21),"") -> 0 | B28: =IF(A28="","",INDEX(Purchase_Entry!B$2:B$5000,21)) -> 0 | C28: =IF(A28="","",INDEX(Purchase_Entry!C$2:C$5000,21)) -> 0 | D28: =IF(A28="","",INDEX(Purchase_Entry!D$2:D$5000,21)) -> 0 | E28: =IF(A28="","",INDEX(Purchase_Entry!K$2:K$5000,21)) -> 0 | F28: =IF(A28="","",INDEX(Purchase_Entry!J$2:J$5000,21)) -> 0 | G28: =IF(A28="","",INDEX(Purchase_Entry!L$2:L$5000,21)) -> 0 | H28: =IF(A28="","",INDEX(Purchase_Entry!M$2:M$5000,21)) -> 0 | I28: =IF(A28="","",INDEX(Purchase_Entry!N$2:N$5000,21)) -> 0 | J28: =IF(A28="","",INDEX(Purchase_Entry!O$2:O$5000,21)) -> 0 | K28: =IF(A28="","",INDEX(Purchase_Entry!P$2:P$5000,21)) -> 0
A29: TOTALS | G29: =SUM(G9:G28) -> 39364.094 | H29: =SUM(H9:H28) -> 3220 | I29: =SUM(I9:I28) -> 42584.094

Sheet Stock_Report
A1: 🐄 STOCK REPORT
A3: Stock Summary:
A4: Total Products: | B4: =COUNTA(Stock_Master!A$2:A$5000) -> 8
A5: Total Stock Value: | B5: =SUMPRODUCT((Stock_Master!F$2:F$5000)*(Stock_Master!H$2:H$5000)) -> 208131
A6: Low Stock Items: | B6: =COUNTIF(Stock_Master!J$2:J$5000,"Reorder") -> 1
A8: Product | B8: Unit | C8: Opening | D8: Purchases | E8: Sales | F8: Current | G8: Reorder Level | H8: Stock Value | I8: Status
A9: =IFERROR(INDEX(Stock_Master!A$2:A$5000,2),"") -> Cow Milk | B9: =IF(A9="","",INDEX(Stock_Master!B$2:B$5000,2)) -> Liter | C9: =IF(A9="","",INDEX(Stock_Master!C$2:C$5000,2)) -> 500 | D9: =IF(A9="","",INDEX(Stock_Master!D$2:D$5000,2)) -> 125 | E9: =IF(A9="","",INDEX(Stock_Master!E$2:E$5000,2)) -> 29.6 | F9: =IF(A9="","",INDEX(Stock_Master!F$2:F$5000,2)) -> 595.4 | G9: =IF(A9="","",INDEX(Stock_Master!G$2:G$5000,2)) -> 100 | H9: =IF(A9="","",INDEX(Stock_Master!I$2:I$5000,2)) -> 38701 | I9: =IF(A9="","",INDEX(Stock_Master!J$2:J$5000,2)) -> In Stock
A10: =IFERROR(INDEX(Stock_Master!A$2:A$5000,3),"") -> Curd (Dahi) | B10: =IF(A10="","",INDEX(Stock_Master!B$2:B$5000,3)) -> Kg | C10: =IF(A10="","",INDEX(Stock_Master!C$2:C$5000,3)) -> 100 | D10: =IF(A10="","",INDEX(Stock_Master!D$2:D$5000,3)) -> 0 | E10: =IF(A10="","",INDEX(Stock_Master!E$2:E$5000,3)) -> 35.2 | F10: =IF(A10="","",INDEX(Stock_Master!F$2:F$5000,3)) -> 64.8 | G10: =IF(A10="","",INDEX(Stock_Master!G$2:G$5000,3)) -> 20 | H10: =IF(A10="","",INDEX(Stock_Master!I$2:I$5000,3)) -> 6480 | I10: =IF(A10="","",INDEX(Stock_Master!J$2:J$5000,3)) -> In Stock
A11: =IFERROR(INDEX(Stock_Master!A$2:A$5000,4),"") -> Ghee | B11: =IF(A11="","",INDEX(Stock_Master!B$2:B$5000,4)) -> Kg | C11: =IF(A11="","",INDEX(Stock_Master!C$2:C$5000,4)) -> 50 | D11: =IF(A11="","",INDEX(Stock_Master!D$2:D$5000,4)) -> 100 | E11: =IF(A11="","",INDEX(Stock_Master!E$2:E$5000,4)) -> 40.8 | F11: =IF(A11="","",INDEX(Stock_Master!F$2:F$5000,4)) -> 109.2 | G11: =IF(A11="","",INDEX(Stock_Master!G$2:G$5000,4)) -> 10 | H11: =IF(A11="","",INDEX(Stock_Master!I$2:I$5000,4)) -> 70980 | I11: =IF(A11="","",INDEX(Stock_Master!J$2:J$5000,4)) -> In Stock
